<sdf version='1.7'>
  <world name='default'>
    <plugin name='welcome' filename='libwelcome.so'/>
    <light name='sun' type='directional'>
      <cast_shadows>1</cast_shadows>
      <pose>0 0 10 0 -0 0</pose>
      <diffuse>0.8 0.8 0.8 1</diffuse>
      <specular>0.2 0.2 0.2 1</specular>
      <attenuation>
        <range>1000</range>
        <constant>0.9</constant>
        <linear>0.01</linear>
        <quadratic>0.001</quadratic>
      </attenuation>
      <direction>-0.5 0.1 -0.9</direction>
      <spot>
        <inner_angle>0</inner_angle>
        <outer_angle>0</outer_angle>
        <falloff>0</falloff>
      </spot>
    </light>
    <model name='ground_plane'>
      <static>1</static>
      <link name='link'>
        <collision name='collision'>
          <geometry>
            <plane>
              <normal>0 0 1</normal>
              <size>100 100</size>
            </plane>
          </geometry>
          <surface>
            <contact>
              <collide_bitmask>65535</collide_bitmask>
              <ode/>
            </contact>
            <friction>
              <ode>
                <mu>100</mu>
                <mu2>50</mu2>
              </ode>
              <torsional>
                <ode/>
              </torsional>
            </friction>
            <bounce/>
          </surface>
          <max_contacts>10</max_contacts>
        </collision>
        <visual name='visual'>
          <cast_shadows>0</cast_shadows>
          <geometry>
            <plane>
              <normal>0 0 1</normal>
              <size>100 100</size>
            </plane>
          </geometry>
          <material>
            <script>
              <uri>file://media/materials/scripts/gazebo.material</uri>
              <name>Gazebo/Grey</name>
            </script>
          </material>
        </visual>
        <self_collide>0</self_collide>
        <enable_wind>0</enable_wind>
        <kinematic>0</kinematic>
      </link>
    </model>
    <gravity>0 0 -9.8</gravity>
    <magnetic_field>6e-06 2.3e-05 -4.2e-05</magnetic_field>
    <atmosphere type='adiabatic'/>
    <physics type='ode'>
      <max_step_size>0.001</max_step_size>
      <real_time_factor>1</real_time_factor>
      <real_time_update_rate>1000</real_time_update_rate>
    </physics>
    <scene>
      <ambient>0.4 0.4 0.4 1</ambient>
      <background>0.7 0.7 0.7 1</background>
      <shadows>1</shadows>
    </scene>
    <wind/>
    <spherical_coordinates>
      <surface_model>EARTH_WGS84</surface_model>
      <latitude_deg>0</latitude_deg>
      <longitude_deg>0</longitude_deg>
      <elevation>0</elevation>
      <heading_deg>0</heading_deg>
    </spherical_coordinates>
    <model name='model_0'>
      <link name='link_0'>
        <inertial>
          <mass>1</mass>
          <inertia>
            <ixx>0.166667</ixx>
            <ixy>0</ixy>
            <ixz>0</ixz>
            <iyy>0.166667</iyy>
            <iyz>0</iyz>
            <izz>0.166667</izz>
          </inertia>
          <pose>0 0 0 0 -0 0</pose>
        </inertial>
        <pose>0.008 0.004 0.692007 0 -0 0</pose>
        <gravity>1</gravity>
        <self_collide>0</self_collide>
        <kinematic>0</kinematic>
        <enable_wind>0</enable_wind>
        <visual name='visual'>
          <pose>0 0 0 0 -0 0</pose>
          <geometry>
            <box>
              <size>1 1 0.1</size>
            </box>
          </geometry>
          <material>
            <lighting>1</lighting>
            <script>
              <uri>file://media/materials/scripts/gazebo.material</uri>
              <name>Gazebo/Grey</name>
            </script>
            <shader type='pixel'>
              <normal_map>__default__</normal_map>
            </shader>
            <ambient>0.3 0.3 0.3 1</ambient>
            <diffuse>0.7 0.7 0.7 1</diffuse>
            <specular>0.01 0.01 0.01 1</specular>
            <emissive>0 0 0 1</emissive>
          </material>
          <transparency>0</transparency>
          <cast_shadows>1</cast_shadows>
        </visual>
        <collision name='collision'>
          <laser_retro>0</laser_retro>
          <max_contacts>10</max_contacts>
          <pose>0 0 0 0 -0 0</pose>
          <geometry>
            <box>
              <size>1 1 0.1</size>
            </box>
          </geometry>
          <surface>
            <friction>
              <ode>
                <mu>1</mu>
                <mu2>1</mu2>
                <fdir1>0 0 0</fdir1>
                <slip1>0</slip1>
                <slip2>0</slip2>
              </ode>
              <torsional>
                <coefficient>1</coefficient>
                <patch_radius>0</patch_radius>
                <surface_radius>0</surface_radius>
                <use_patch_radius>1</use_patch_radius>
                <ode>
                  <slip>0</slip>
                </ode>
              </torsional>
            </friction>
            <bounce>
              <restitution_coefficient>0</restitution_coefficient>
              <threshold>1e+06</threshold>
            </bounce>
            <contact>
              <collide_without_contact>0</collide_without_contact>
              <collide_without_contact_bitmask>1</collide_without_contact_bitmask>
              <collide_bitmask>1</collide_bitmask>
              <ode>
                <soft_cfm>0</soft_cfm>
                <soft_erp>0.2</soft_erp>
                <kp>1e+13</kp>
                <kd>1</kd>
                <max_vel>0.01</max_vel>
                <min_depth>0</min_depth>
              </ode>
              <bullet>
                <split_impulse>1</split_impulse>
                <split_impulse_penetration_threshold>-0.01</split_impulse_penetration_threshold>
                <soft_cfm>0</soft_cfm>
                <soft_erp>0.2</soft_erp>
                <kp>1e+13</kp>
                <kd>1</kd>
              </bullet>
            </contact>
          </surface>
        </collision>
      </link>
      <link name='link_1'>
        <inertial>
          <mass>1</mass>
          <inertia>
            <ixx>0.145833</ixx>
            <ixy>0</ixy>
            <ixz>0</ixz>
            <iyy>0.145833</iyy>
            <iyz>0</iyz>
            <izz>0.125</izz>
          </inertia>
          <pose>0 0 0 0 -0 0</pose>
        </inertial>
        <pose>-0.012 -0.016 0.142007 0 -0 0</pose>
        <gravity>1</gravity>
        <self_collide>0</self_collide>
        <kinematic>0</kinematic>
        <enable_wind>0</enable_wind>
        <visual name='visual'>
          <pose>0 0 0 0 -0 0</pose>
          <geometry>
            <cylinder>
              <radius>0.1</radius>
              <length>1</length>
            </cylinder>
          </geometry>
          <material>
            <lighting>1</lighting>
            <script>
              <uri>file://media/materials/scripts/gazebo.material</uri>
              <name>Gazebo/Grey</name>
            </script>
            <shader type='pixel'>
              <normal_map>__default__</normal_map>
            </shader>
            <ambient>0.3 0.3 0.3 1</ambient>
            <diffuse>0.7 0.7 0.7 1</diffuse>
            <specular>0.01 0.01 0.01 1</specular>
            <emissive>0 0 0 1</emissive>
          </material>
          <transparency>0</transparency>
          <cast_shadows>1</cast_shadows>
        </visual>
        <collision name='collision'>
          <laser_retro>0</laser_retro>
          <max_contacts>10</max_contacts>
          <pose>0 0 0 0 -0 0</pose>
          <geometry>
            <cylinder>
              <radius>0.1</radius>
              <length>1</length>
            </cylinder>
          </geometry>
          <surface>
            <friction>
              <ode>
                <mu>1</mu>
                <mu2>1</mu2>
                <fdir1>0 0 0</fdir1>
                <slip1>0</slip1>
                <slip2>0</slip2>
              </ode>
              <torsional>
                <coefficient>1</coefficient>
                <patch_radius>0</patch_radius>
                <surface_radius>0</surface_radius>
                <use_patch_radius>1</use_patch_radius>
                <ode>
                  <slip>0</slip>
                </ode>
              </torsional>
            </friction>
            <bounce>
              <restitution_coefficient>0</restitution_coefficient>
              <threshold>1e+06</threshold>
            </bounce>
            <contact>
              <collide_without_contact>0</collide_without_contact>
              <collide_without_contact_bitmask>1</collide_without_contact_bitmask>
              <collide_bitmask>1</collide_bitmask>
              <ode>
                <soft_cfm>0</soft_cfm>
                <soft_erp>0.2</soft_erp>
                <kp>1e+13</kp>
                <kd>1</kd>
                <max_vel>0.01</max_vel>
                <min_depth>0</min_depth>
              </ode>
              <bullet>
                <split_impulse>1</split_impulse>
                <split_impulse_penetration_threshold>-0.01</split_impulse_penetration_threshold>
                <soft_cfm>0</soft_cfm>
                <soft_erp>0.2</soft_erp>
                <kp>1e+13</kp>
                <kd>1</kd>
              </bullet>
            </contact>
          </surface>
        </collision>
      </link>
      <link name='link_2'>
        <inertial>
          <mass>1</mass>
          <inertia>
            <ixx>0.166667</ixx>
            <ixy>0</ixy>
            <ixz>0</ixz>
            <iyy>0.166667</iyy>
            <iyz>0</iyz>
            <izz>0.166667</izz>
          </inertia>
          <pose>0 0 0 0 -0 0</pose>
        </inertial>
        <pose>-0.012 0.004 -0.307993 0 -0 0</pose>
        <gravity>1</gravity>
        <self_collide>0</self_collide>
        <kinematic>0</kinematic>
        <enable_wind>0</enable_wind>
        <visual name='visual'>
          <pose>0 0 0 0 -0 0</pose>
          <geometry>
            <box>
              <size>0.2 1 0.1</size>
            </box>
          </geometry>
          <material>
            <lighting>1</lighting>
            <script>
              <uri>file://media/materials/scripts/gazebo.material</uri>
              <name>Gazebo/Grey</name>
            </script>
            <shader type='pixel'>
              <normal_map>__default__</normal_map>
            </shader>
            <ambient>0.3 0.3 0.3 1</ambient>
            <diffuse>0.7 0.7 0.7 1</diffuse>
            <specular>0.01 0.01 0.01 1</specular>
            <emissive>0 0 0 1</emissive>
          </material>
          <transparency>0</transparency>
          <cast_shadows>1</cast_shadows>
        </visual>
        <collision name='collision'>
          <laser_retro>0</laser_retro>
          <max_contacts>10</max_contacts>
          <pose>0 0 0 0 -0 0</pose>
          <geometry>
            <box>
              <size>0.2 1 0.1</size>
            </box>
          </geometry>
          <surface>
            <friction>
              <ode>
                <mu>1</mu>
                <mu2>1</mu2>
                <fdir1>0 0 0</fdir1>
                <slip1>0</slip1>
                <slip2>0</slip2>
              </ode>
              <torsional>
                <coefficient>1</coefficient>
                <patch_radius>0</patch_radius>
                <surface_radius>0</surface_radius>
                <use_patch_radius>1</use_patch_radius>
                <ode>
                  <slip>0</slip>
                </ode>
              </torsional>
            </friction>
            <bounce>
              <restitution_coefficient>0</restitution_coefficient>
              <threshold>1e+06</threshold>
            </bounce>
            <contact>
              <collide_without_contact>0</collide_without_contact>
              <collide_without_contact_bitmask>1</collide_without_contact_bitmask>
              <collide_bitmask>1</collide_bitmask>
              <ode>
                <soft_cfm>0</soft_cfm>
                <soft_erp>0.2</soft_erp>
                <kp>1e+13</kp>
                <kd>1</kd>
                <max_vel>0.01</max_vel>
                <min_depth>0</min_depth>
              </ode>
              <bullet>
                <split_impulse>1</split_impulse>
                <split_impulse_penetration_threshold>-0.01</split_impulse_penetration_threshold>
                <soft_cfm>0</soft_cfm>
                <soft_erp>0.2</soft_erp>
                <kp>1e+13</kp>
                <kd>1</kd>
              </bullet>
            </contact>
          </surface>
        </collision>
      </link>
      <link name='link_3'>
        <inertial>
          <mass>1</mass>
          <inertia>
            <ixx>0.145833</ixx>
            <ixy>0</ixy>
            <ixz>0</ixz>
            <iyy>0.145833</iyy>
            <iyz>0</iyz>
            <izz>0.125</izz>
          </inertia>
          <pose>0 0 0 1.57 -0 0</pose>
        </inertial>
        <pose>0.008 -0.546159 -0.263029 1.57 -0 0</pose>
        <gravity>1</gravity>
        <self_collide>0</self_collide>
        <kinematic>0</kinematic>
        <enable_wind>0</enable_wind>
        <visual name='visual'>
          <pose>0 0 0 0 -0 0</pose>
          <geometry>
            <cylinder>
              <radius>0.2</radius>
              <length>0.1</length>
            </cylinder>
          </geometry>
          <material>
            <lighting>1</lighting>
            <script>
              <uri>file://media/materials/scripts/gazebo.material</uri>
              <name>Gazebo/Grey</name>
            </script>
            <shader type='pixel'>
              <normal_map>__default__</normal_map>
            </shader>
            <ambient>0.3 0.3 0.3 1</ambient>
            <diffuse>0.7 0.7 0.7 1</diffuse>
            <specular>0.01 0.01 0.01 1</specular>
            <emissive>0 0 0 1</emissive>
          </material>
          <transparency>0</transparency>
          <cast_shadows>1</cast_shadows>
        </visual>
        <collision name='collision'>
          <laser_retro>0</laser_retro>
          <max_contacts>10</max_contacts>
          <pose>0 0 0 0 -0 0</pose>
          <geometry>
            <cylinder>
              <radius>0.2</radius>
              <length>0.1</length>
            </cylinder>
          </geometry>
          <surface>
            <friction>
              <ode>
                <mu>1</mu>
                <mu2>1</mu2>
                <fdir1>0 0 0</fdir1>
                <slip1>0</slip1>
                <slip2>0</slip2>
              </ode>
              <torsional>
                <coefficient>1</coefficient>
                <patch_radius>0</patch_radius>
                <surface_radius>0</surface_radius>
                <use_patch_radius>1</use_patch_radius>
                <ode>
                  <slip>0</slip>
                </ode>
              </torsional>
            </friction>
            <bounce>
              <restitution_coefficient>0</restitution_coefficient>
              <threshold>1e+06</threshold>
            </bounce>
            <contact>
              <collide_without_contact>0</collide_without_contact>
              <collide_without_contact_bitmask>1</collide_without_contact_bitmask>
              <collide_bitmask>1</collide_bitmask>
              <ode>
                <soft_cfm>0</soft_cfm>
                <soft_erp>0.2</soft_erp>
                <kp>1e+13</kp>
                <kd>1</kd>
                <max_vel>0.01</max_vel>
                <min_depth>0</min_depth>
              </ode>
              <bullet>
                <split_impulse>1</split_impulse>
                <split_impulse_penetration_threshold>-0.01</split_impulse_penetration_threshold>
                <soft_cfm>0</soft_cfm>
                <soft_erp>0.2</soft_erp>
                <kp>1e+13</kp>
                <kd>1</kd>
              </bullet>
            </contact>
          </surface>
        </collision>
      </link>
      <link name='link_3_clone'>
        <inertial>
          <mass>1</mass>
          <inertia>
            <ixx>0.145833</ixx>
            <ixy>0</ixy>
            <ixz>0</ixz>
            <iyy>0.145833</iyy>
            <iyz>0</iyz>
            <izz>0.125</izz>
          </inertia>
          <pose>0 0 0 0 -0 0</pose>
        </inertial>
        <pose>0.008 0.554159 -0.262993 1.57 -0 0</pose>
        <gravity>1</gravity>
        <self_collide>0</self_collide>
        <kinematic>0</kinematic>
        <enable_wind>0</enable_wind>
        <visual name='visual'>
          <pose>0 0 0 0 -0 0</pose>
          <geometry>
            <cylinder>
              <radius>0.2</radius>
              <length>0.1</length>
            </cylinder>
          </geometry>
          <material>
            <lighting>1</lighting>
            <script>
              <uri>file://media/materials/scripts/gazebo.material</uri>
              <name>Gazebo/Grey</name>
            </script>
            <shader type='pixel'>
              <normal_map>__default__</normal_map>
            </shader>
            <ambient>0.3 0.3 0.3 1</ambient>
            <diffuse>0.7 0.7 0.7 1</diffuse>
            <specular>0.01 0.01 0.01 1</specular>
            <emissive>0 0 0 1</emissive>
          </material>
          <transparency>0</transparency>
          <cast_shadows>1</cast_shadows>
        </visual>
        <collision name='collision'>
          <laser_retro>0</laser_retro>
          <max_contacts>10</max_contacts>
          <pose>0 0 0 0 -0 0</pose>
          <geometry>
            <cylinder>
              <radius>0.2</radius>
              <length>0.1</length>
            </cylinder>
          </geometry>
          <surface>
            <friction>
              <ode>
                <mu>1</mu>
                <mu2>1</mu2>
                <fdir1>0 0 0</fdir1>
                <slip1>0</slip1>
                <slip2>0</slip2>
              </ode>
              <torsional>
                <coefficient>1</coefficient>
                <patch_radius>0</patch_radius>
                <surface_radius>0</surface_radius>
                <use_patch_radius>1</use_patch_radius>
                <ode>
                  <slip>0</slip>
                </ode>
              </torsional>
            </friction>
            <bounce>
              <restitution_coefficient>0</restitution_coefficient>
              <threshold>1e+06</threshold>
            </bounce>
            <contact>
              <collide_without_contact>0</collide_without_contact>
              <collide_without_contact_bitmask>1</collide_without_contact_bitmask>
              <collide_bitmask>1</collide_bitmask>
              <ode>
                <soft_cfm>0</soft_cfm>
                <soft_erp>0.2</soft_erp>
                <kp>1e+13</kp>
                <kd>1</kd>
                <max_vel>0.01</max_vel>
                <min_depth>0</min_depth>
              </ode>
              <bullet>
                <split_impulse>1</split_impulse>
                <split_impulse_penetration_threshold>-0.01</split_impulse_penetration_threshold>
                <soft_cfm>0</soft_cfm>
                <soft_erp>0.2</soft_erp>
                <kp>1e+13</kp>
                <kd>1</kd>
              </bullet>
            </contact>
          </surface>
        </collision>
      </link>
      <joint name='link_0_JOINT_0' type='fixed'>
        <parent>link_0</parent>
        <child>link_1</child>
        <pose>0 0 0 0 -0.01 0</pose>
        <physics>
          <ode>
            <limit>
              <cfm>0</cfm>
              <erp>0.2</erp>
            </limit>
            <suspension>
              <cfm>0</cfm>
              <erp>0.2</erp>
            </suspension>
          </ode>
        </physics>
      </joint>
      <joint name='link_1_JOINT_1' type='fixed'>
        <parent>link_1</parent>
        <child>link_2</child>
        <pose>0 0 0 0 -0 0</pose>
        <physics>
          <ode>
            <limit>
              <cfm>0</cfm>
              <erp>0.2</erp>
            </limit>
            <suspension>
              <cfm>0</cfm>
              <erp>0.2</erp>
            </suspension>
          </ode>
        </physics>
      </joint>
      <joint name='link_2_JOINT_3' type='revolute'>
        <parent>link_2</parent>
        <child>link_3</child>
        <pose>0 0 0 0 -0 0</pose>
        <axis>
          <xyz>0 0 1</xyz>
          <limit>
            <lower>-1.79769e+308</lower>
            <upper>1.79769e+308</upper>
            <effort>-1</effort>
            <velocity>-1</velocity>
          </limit>
          <dynamics>
            <spring_reference>0</spring_reference>
            <spring_stiffness>0</spring_stiffness>
            <damping>0</damping>
          </dynamics>
        </axis>
        <physics>
          <ode>
            <limit>
              <cfm>0</cfm>
              <erp>0.2</erp>
            </limit>
            <suspension>
              <cfm>0</cfm>
              <erp>0.2</erp>
            </suspension>
          </ode>
        </physics>
      </joint>
      <joint name='link_2_JOINT_4' type='revolute'>
        <parent>link_2</parent>
        <child>link_3_clone</child>
        <pose>0 0 0 0 -0 0</pose>
        <axis>
          <xyz>0 0 1</xyz>
          <limit>
            <lower>-1.79769e+308</lower>
            <upper>1.79769e+308</upper>
            <effort>-1</effort>
            <velocity>-1</velocity>
          </limit>
          <dynamics>
            <spring_reference>0</spring_reference>
            <spring_stiffness>0</spring_stiffness>
            <damping>0</damping>
          </dynamics>
        </axis>
        <physics>
          <ode>
            <limit>
              <cfm>0</cfm>
              <erp>0.2</erp>
            </limit>
            <suspension>
              <cfm>0</cfm>
              <erp>0.2</erp>
            </suspension>
          </ode>
        </physics>
      </joint>
      <static>0</static>
      <allow_auto_disable>1</allow_auto_disable>
      <pose>0.939777 -0.09685 0.099927 0 -0 0</pose>
    </model>
    <model name='model'>
      <pose>14.5657 -5.80006 0 0 -0 0</pose>
      <link name='Door_1'>
        <collision name='Door_1_Collision'>
          <geometry>
            <box>
              <size>0.9 0.17 2</size>
            </box>
          </geometry>
          <pose>0 0 1 0 -0 0</pose>
          <max_contacts>10</max_contacts>
          <surface>
            <contact>
              <ode/>
            </contact>
            <bounce/>
            <friction>
              <torsional>
                <ode/>
              </torsional>
              <ode/>
            </friction>
          </surface>
        </collision>
        <visual name='Door_1_Visual'>
          <pose>0 0 1 0 -0 0</pose>
          <geometry>
            <box>
              <size>0.9 0.17 2</size>
            </box>
          </geometry>
          <material>
            <script>
              <uri>file://media/materials/scripts/gazebo.material</uri>
              <name>Gazebo/Grey</name>
            </script>
          </material>
        </visual>
        <pose>-1.07562 0.060898 0 0 -0 0</pose>
        <self_collide>0</self_collide>
        <enable_wind>0</enable_wind>
        <kinematic>0</kinematic>
      </link>
      <link name='Wall_0'>
        <pose>-0.12709 3.49959 0 0 -0 0</pose>
        <visual name='Wall_0_Visual_0'>
          <pose>-2.02192 0 1.25 0 -0 0</pose>
          <geometry>
            <box>
              <size>0.956165 0.15 2.5</size>
            </box>
          </geometry>
          <material>
            <script>
              <uri>file://media/materials/scripts/gazebo.material</uri>
              <name>Gazebo/Grey</name>
            </script>
            <ambient>0.12549 0.290196 0.529412 1</ambient>
          </material>
          <meta>
            <layer>0</layer>
          </meta>
        </visual>
        <collision name='Wall_0_Collision_0'>
          <geometry>
            <box>
              <size>0.956165 0.15 2.5</size>
            </box>
          </geometry>
          <pose>-2.02192 0 1.25 0 -0 0</pose>
          <max_contacts>10</max_contacts>
          <surface>
            <contact>
              <ode/>
            </contact>
            <bounce/>
            <friction>
              <torsional>
                <ode/>
              </torsional>
              <ode/>
            </friction>
          </surface>
        </collision>
        <visual name='Wall_0_Visual_1'>
          <pose>0.478083 0 0.25 0 -0 0</pose>
          <geometry>
            <box>
              <size>4.04383 0.15 0.5</size>
            </box>
          </geometry>
          <material>
            <script>
              <uri>file://media/materials/scripts/gazebo.material</uri>
              <name>Gazebo/Grey</name>
            </script>
            <ambient>0.12549 0.290196 0.529412 1</ambient>
          </material>
          <meta>
            <layer>0</layer>
          </meta>
        </visual>
        <collision name='Wall_0_Collision_1'>
          <geometry>
            <box>
              <size>4.04383 0.15 0.5</size>
            </box>
          </geometry>
          <pose>0.478083 0 0.25 0 -0 0</pose>
          <max_contacts>10</max_contacts>
          <surface>
            <contact>
              <ode/>
            </contact>
            <bounce/>
            <friction>
              <torsional>
                <ode/>
              </torsional>
              <ode/>
            </friction>
          </surface>
        </collision>
        <visual name='Wall_0_Visual_2'>
          <pose>-0.073177 0 1.5 0 -0 0</pose>
          <geometry>
            <box>
              <size>1.34132 0.15 2</size>
            </box>
          </geometry>
          <material>
            <script>
              <uri>file://media/materials/scripts/gazebo.material</uri>
              <name>Gazebo/Grey</name>
            </script>
            <ambient>0.12549 0.290196 0.529412 1</ambient>
          </material>
          <meta>
            <layer>0</layer>
          </meta>
        </visual>
        <collision name='Wall_0_Collision_2'>
          <geometry>
            <box>
              <size>1.34132 0.15 2</size>
            </box>
          </geometry>
          <pose>-0.073177 0 1.5 0 -0 0</pose>
          <max_contacts>10</max_contacts>
          <surface>
            <contact>
              <ode/>
            </contact>
            <bounce/>
            <friction>
              <torsional>
                <ode/>
              </torsional>
              <ode/>
            </friction>
          </surface>
        </collision>
        <visual name='Wall_0_Visual_3'>
          <pose>1.94874 0 1.5 0 -0 0</pose>
          <geometry>
            <box>
              <size>1.10252 0.15 2</size>
            </box>
          </geometry>
          <material>
            <script>
              <uri>file://media/materials/scripts/gazebo.material</uri>
              <name>Gazebo/Grey</name>
            </script>
            <ambient>0.12549 0.290196 0.529412 1</ambient>
          </material>
          <meta>
            <layer>0</layer>
          </meta>
        </visual>
        <collision name='Wall_0_Collision_3'>
          <geometry>
            <box>
              <size>1.10252 0.15 2</size>
            </box>
          </geometry>
          <pose>1.94874 0 1.5 0 -0 0</pose>
          <max_contacts>10</max_contacts>
          <surface>
            <contact>
              <ode/>
            </contact>
            <bounce/>
            <friction>
              <torsional>
                <ode/>
              </torsional>
              <ode/>
            </friction>
          </surface>
        </collision>
        <visual name='Wall_0_Visual_4'>
          <pose>-1.14383 0 1.9 0 -0 0</pose>
          <geometry>
            <box>
              <size>0.8 0.15 1.2</size>
            </box>
          </geometry>
          <material>
            <script>
              <uri>file://media/materials/scripts/gazebo.material</uri>
              <name>Gazebo/Grey</name>
            </script>
            <ambient>0.12549 0.290196 0.529412 1</ambient>
          </material>
          <meta>
            <layer>0</layer>
          </meta>
        </visual>
        <collision name='Wall_0_Collision_4'>
          <geometry>
            <box>
              <size>0.8 0.15 1.2</size>
            </box>
          </geometry>
          <pose>-1.14383 0 1.9 0 -0 0</pose>
          <max_contacts>10</max_contacts>
          <surface>
            <contact>
              <ode/>
            </contact>
            <bounce/>
            <friction>
              <torsional>
                <ode/>
              </torsional>
              <ode/>
            </friction>
          </surface>
        </collision>
        <visual name='Wall_0_Visual_5'>
          <pose>0.997481 0 1.9 0 -0 0</pose>
          <geometry>
            <box>
              <size>0.8 0.15 1.2</size>
            </box>
          </geometry>
          <material>
            <script>
              <uri>file://media/materials/scripts/gazebo.material</uri>
              <name>Gazebo/Grey</name>
            </script>
            <ambient>0.12549 0.290196 0.529412 1</ambient>
          </material>
          <meta>
            <layer>0</layer>
          </meta>
        </visual>
        <collision name='Wall_0_Collision_5'>
          <geometry>
            <box>
              <size>0.8 0.15 1.2</size>
            </box>
          </geometry>
          <pose>0.997481 0 1.9 0 -0 0</pose>
          <max_contacts>10</max_contacts>
          <surface>
            <contact>
              <ode/>
            </contact>
            <bounce/>
            <friction>
              <torsional>
                <ode/>
              </torsional>
              <ode/>
            </friction>
          </surface>
        </collision>
        <self_collide>0</self_collide>
        <enable_wind>0</enable_wind>
        <kinematic>0</kinematic>
      </link>
      <link name='Wall_1'>
        <collision name='Wall_1_Collision'>
          <geometry>
            <box>
              <size>3.5 0.15 2.5</size>
            </box>
          </geometry>
          <pose>0 0 1.25 0 -0 0</pose>
          <max_contacts>10</max_contacts>
          <surface>
            <contact>
              <ode/>
            </contact>
            <bounce/>
            <friction>
              <torsional>
                <ode/>
              </torsional>
              <ode/>
            </friction>
          </surface>
        </collision>
        <visual name='Wall_1_Visual'>
          <pose>0 0 1.25 0 -0 0</pose>
          <geometry>
            <box>
              <size>3.5 0.15 2.5</size>
            </box>
          </geometry>
          <material>
            <script>
              <uri>file://media/materials/scripts/gazebo.material</uri>
              <name>Gazebo/Grey</name>
            </script>
            <ambient>0.435294 0.796078 0.67451 1</ambient>
          </material>
          <meta>
            <layer>0</layer>
          </meta>
        </visual>
        <pose>2.29791 1.82459 0 0 -0 -1.5708</pose>
        <self_collide>0</self_collide>
        <enable_wind>0</enable_wind>
        <kinematic>0</kinematic>
      </link>
      <link name='Wall_12'>
        <pose>-0.00209 -4.20041 0 0 -0 0</pose>
        <visual name='Wall_12_Visual_0'>
          <pose>-2.28061 0 1.25 0 -0 0</pose>
          <geometry>
            <box>
              <size>0.688775 0.15 2.5</size>
            </box>
          </geometry>
          <material>
            <script>
              <uri>file://media/materials/scripts/gazebo.material</uri>
              <name>Gazebo/CeilingTiled</name>
            </script>
            <ambient>0.996078 0.47451 0.0196078 1</ambient>
          </material>
          <meta>
            <layer>0</layer>
          </meta>
        </visual>
        <collision name='Wall_12_Collision_0'>
          <geometry>
            <box>
              <size>0.688775 0.15 2.5</size>
            </box>
          </geometry>
          <pose>-2.28061 0 1.25 0 -0 0</pose>
          <max_contacts>10</max_contacts>
          <surface>
            <contact>
              <ode/>
            </contact>
            <bounce/>
            <friction>
              <torsional>
                <ode/>
              </torsional>
              <ode/>
            </friction>
          </surface>
        </collision>
        <visual name='Wall_12_Visual_1'>
          <pose>0.344388 0 0.25 0 -0 0</pose>
          <geometry>
            <box>
              <size>4.56123 0.15 0.5</size>
            </box>
          </geometry>
          <material>
            <script>
              <uri>file://media/materials/scripts/gazebo.material</uri>
              <name>Gazebo/CeilingTiled</name>
            </script>
            <ambient>0.996078 0.47451 0.0196078 1</ambient>
          </material>
          <meta>
            <layer>0</layer>
          </meta>
        </visual>
        <collision name='Wall_12_Collision_1'>
          <geometry>
            <box>
              <size>4.56123 0.15 0.5</size>
            </box>
          </geometry>
          <pose>0.344388 0 0.25 0 -0 0</pose>
          <max_contacts>10</max_contacts>
          <surface>
            <contact>
              <ode/>
            </contact>
            <bounce/>
            <friction>
              <torsional>
                <ode/>
              </torsional>
              <ode/>
            </friction>
          </surface>
        </collision>
        <visual name='Wall_12_Visual_2'>
          <pose>0.744388 0 1.5 0 -0 0</pose>
          <geometry>
            <box>
              <size>3.76123 0.15 2</size>
            </box>
          </geometry>
          <material>
            <script>
              <uri>file://media/materials/scripts/gazebo.material</uri>
              <name>Gazebo/CeilingTiled</name>
            </script>
            <ambient>0.996078 0.47451 0.0196078 1</ambient>
          </material>
          <meta>
            <layer>0</layer>
          </meta>
        </visual>
        <collision name='Wall_12_Collision_2'>
          <geometry>
            <box>
              <size>3.76123 0.15 2</size>
            </box>
          </geometry>
          <pose>0.744388 0 1.5 0 -0 0</pose>
          <max_contacts>10</max_contacts>
          <surface>
            <contact>
              <ode/>
            </contact>
            <bounce/>
            <friction>
              <torsional>
                <ode/>
              </torsional>
              <ode/>
            </friction>
          </surface>
        </collision>
        <visual name='Wall_12_Visual_3'>
          <pose>-1.53622 0 1.9 0 -0 0</pose>
          <geometry>
            <box>
              <size>0.8 0.15 1.2</size>
            </box>
          </geometry>
          <material>
            <script>
              <uri>file://media/materials/scripts/gazebo.material</uri>
              <name>Gazebo/CeilingTiled</name>
            </script>
            <ambient>0.996078 0.47451 0.0196078 1</ambient>
          </material>
          <meta>
            <layer>0</layer>
          </meta>
        </visual>
        <collision name='Wall_12_Collision_3'>
          <geometry>
            <box>
              <size>0.8 0.15 1.2</size>
            </box>
          </geometry>
          <pose>-1.53622 0 1.9 0 -0 0</pose>
          <max_contacts>10</max_contacts>
          <surface>
            <contact>
              <ode/>
            </contact>
            <bounce/>
            <friction>
              <torsional>
                <ode/>
              </torsional>
              <ode/>
            </friction>
          </surface>
        </collision>
        <self_collide>0</self_collide>
        <enable_wind>0</enable_wind>
        <kinematic>0</kinematic>
      </link>
      <link name='Wall_13'>
        <collision name='Wall_13_Collision'>
          <geometry>
            <box>
              <size>4.50718 0.15 2.5</size>
            </box>
          </geometry>
          <pose>0 0 1.25 0 -0 0</pose>
          <max_contacts>10</max_contacts>
          <surface>
            <contact>
              <ode/>
            </contact>
            <bounce/>
            <friction>
              <torsional>
                <ode/>
              </torsional>
              <ode/>
            </friction>
          </surface>
        </collision>
        <visual name='Wall_13_Visual'>
          <pose>0 0 1.25 0 -0 0</pose>
          <geometry>
            <box>
              <size>4.50718 0.15 2.5</size>
            </box>
          </geometry>
          <material>
            <script>
              <uri>file://media/materials/scripts/gazebo.material</uri>
              <name>Gazebo/CeilingTiled</name>
            </script>
            <ambient>0.996078 0.47451 0.0196078 1</ambient>
          </material>
          <meta>
            <layer>0</layer>
          </meta>
        </visual>
        <pose>2.42291 -2.02541 0 0 -0 1.6282</pose>
        <self_collide>0</self_collide>
        <enable_wind>0</enable_wind>
        <kinematic>0</kinematic>
      </link>
      <link name='Wall_2'>
        <collision name='Wall_2_Collision'>
          <geometry>
            <box>
              <size>5 0.15 2.5</size>
            </box>
          </geometry>
          <pose>0 0 1.25 0 -0 0</pose>
          <max_contacts>10</max_contacts>
          <surface>
            <contact>
              <ode/>
            </contact>
            <bounce/>
            <friction>
              <torsional>
                <ode/>
              </torsional>
              <ode/>
            </friction>
          </surface>
        </collision>
        <visual name='Wall_2_Visual'>
          <pose>0 0 1.25 0 -0 0</pose>
          <geometry>
            <box>
              <size>5 0.15 2.5</size>
            </box>
          </geometry>
          <material>
            <script>
              <uri>file://media/materials/scripts/gazebo.material</uri>
              <name>Gazebo/Wood</name>
            </script>
            <ambient>0.435294 0.796078 0.67451 1</ambient>
          </material>
          <meta>
            <layer>0</layer>
          </meta>
        </visual>
        <pose>-0.12709 0.14959 0 0 -0 3.14159</pose>
        <self_collide>0</self_collide>
        <enable_wind>0</enable_wind>
        <kinematic>0</kinematic>
      </link>
      <link name='Wall_3'>
        <collision name='Wall_3_Collision'>
          <geometry>
            <box>
              <size>3.5 0.15 2.5</size>
            </box>
          </geometry>
          <pose>0 0 1.25 0 -0 0</pose>
          <max_contacts>10</max_contacts>
          <surface>
            <contact>
              <ode/>
            </contact>
            <bounce/>
            <friction>
              <torsional>
                <ode/>
              </torsional>
              <ode/>
            </friction>
          </surface>
        </collision>
        <visual name='Wall_3_Visual'>
          <pose>0 0 1.25 0 -0 0</pose>
          <geometry>
            <box>
              <size>3.5 0.15 2.5</size>
            </box>
          </geometry>
          <material>
            <script>
              <uri>file://media/materials/scripts/gazebo.material</uri>
              <name>Gazebo/Grey</name>
            </script>
            <ambient>0.435294 0.796078 0.67451 1</ambient>
          </material>
          <meta>
            <layer>0</layer>
          </meta>
        </visual>
        <pose>-2.55209 1.82459 0 0 -0 1.5708</pose>
        <self_collide>0</self_collide>
        <enable_wind>0</enable_wind>
        <kinematic>0</kinematic>
      </link>
      <link name='Wall_5'>
        <collision name='Wall_5_Collision'>
          <geometry>
            <box>
              <size>1.25 0.15 2.5</size>
            </box>
          </geometry>
          <pose>0 0 1.25 0 -0 0</pose>
          <max_contacts>10</max_contacts>
          <surface>
            <contact>
              <ode/>
            </contact>
            <bounce/>
            <friction>
              <torsional>
                <ode/>
              </torsional>
              <ode/>
            </friction>
          </surface>
        </collision>
        <visual name='Wall_5_Visual'>
          <pose>0 0 1.25 0 -0 0</pose>
          <geometry>
            <box>
              <size>1.25 0.15 2.5</size>
            </box>
          </geometry>
          <material>
            <script>
              <uri>file://media/materials/scripts/gazebo.material</uri>
              <name>Gazebo/Grey</name>
            </script>
            <ambient>1 1 1 1</ambient>
          </material>
          <meta>
            <layer>0</layer>
          </meta>
        </visual>
        <pose>-1.85152 2.09583 0 0 -0 3.14159</pose>
        <self_collide>0</self_collide>
        <enable_wind>0</enable_wind>
        <kinematic>0</kinematic>
      </link>
      <link name='Wall_6'>
        <pose>-0.101515 2.09583 0 0 -0 0</pose>
        <visual name='Wall_6_Visual_0'>
          <pose>-1.92073 0 1.25 0 -0 0</pose>
          <geometry>
            <box>
              <size>0.908541 0.15 2.5</size>
            </box>
          </geometry>
          <material>
            <script>
              <uri>file://media/materials/scripts/gazebo.material</uri>
              <name>Gazebo/Grey</name>
            </script>
            <ambient>0.760784 0.662745 0.627451 1</ambient>
          </material>
          <meta>
            <layer>0</layer>
          </meta>
        </visual>
        <collision name='Wall_6_Collision_0'>
          <geometry>
            <box>
              <size>0.908541 0.15 2.5</size>
            </box>
          </geometry>
          <pose>-1.92073 0 1.25 0 -0 0</pose>
          <max_contacts>10</max_contacts>
          <surface>
            <contact>
              <ode/>
            </contact>
            <bounce/>
            <friction>
              <torsional>
                <ode/>
              </torsional>
              <ode/>
            </friction>
          </surface>
        </collision>
        <visual name='Wall_6_Visual_1'>
          <pose>0.904271 0 1.25 0 -0 0</pose>
          <geometry>
            <box>
              <size>2.94146 0.15 2.5</size>
            </box>
          </geometry>
          <material>
            <script>
              <uri>file://media/materials/scripts/gazebo.material</uri>
              <name>Gazebo/Grey</name>
            </script>
            <ambient>0.760784 0.662745 0.627451 1</ambient>
          </material>
          <meta>
            <layer>0</layer>
          </meta>
        </visual>
        <collision name='Wall_6_Collision_1'>
          <geometry>
            <box>
              <size>2.94146 0.15 2.5</size>
            </box>
          </geometry>
          <pose>0.904271 0 1.25 0 -0 0</pose>
          <max_contacts>10</max_contacts>
          <surface>
            <contact>
              <ode/>
            </contact>
            <bounce/>
            <friction>
              <torsional>
                <ode/>
              </torsional>
              <ode/>
            </friction>
          </surface>
        </collision>
        <visual name='Wall_6_Visual_2'>
          <pose>-1.01646 0 2.25 0 -0 0</pose>
          <geometry>
            <box>
              <size>0.9 0.15 0.5</size>
            </box>
          </geometry>
          <material>
            <script>
              <uri>file://media/materials/scripts/gazebo.material</uri>
              <name>Gazebo/Grey</name>
            </script>
            <ambient>0.760784 0.662745 0.627451 1</ambient>
          </material>
          <meta>
            <layer>0</layer>
          </meta>
        </visual>
        <collision name='Wall_6_Collision_2'>
          <geometry>
            <box>
              <size>0.9 0.15 0.5</size>
            </box>
          </geometry>
          <pose>-1.01646 0 2.25 0 -0 0</pose>
          <max_contacts>10</max_contacts>
          <surface>
            <contact>
              <ode/>
            </contact>
            <bounce/>
            <friction>
              <torsional>
                <ode/>
              </torsional>
              <ode/>
            </friction>
          </surface>
        </collision>
        <self_collide>0</self_collide>
        <enable_wind>0</enable_wind>
        <kinematic>0</kinematic>
      </link>
      <link name='Wall_8'>
        <pose>-2.55209 -2.02541 0 0 -0 -1.5708</pose>
        <visual name='Wall_8_Visual_0'>
          <pose>-1.50477 0 1.25 0 -0 0</pose>
          <geometry>
            <box>
              <size>1.49045 0.15 2.5</size>
            </box>
          </geometry>
          <material>
            <script>
              <uri>file://media/materials/scripts/gazebo.material</uri>
              <name>Gazebo/Wood</name>
            </script>
            <ambient>0.996078 0.47451 0.0196078 1</ambient>
          </material>
          <meta>
            <layer>0</layer>
          </meta>
        </visual>
        <collision name='Wall_8_Collision_0'>
          <geometry>
            <box>
              <size>1.49045 0.15 2.5</size>
            </box>
          </geometry>
          <pose>-1.50477 0 1.25 0 -0 0</pose>
          <max_contacts>10</max_contacts>
          <surface>
            <contact>
              <ode/>
            </contact>
            <bounce/>
            <friction>
              <torsional>
                <ode/>
              </torsional>
              <ode/>
            </friction>
          </surface>
        </collision>
        <visual name='Wall_8_Visual_1'>
          <pose>0.745225 0 0.25 0 -0 0</pose>
          <geometry>
            <box>
              <size>3.00955 0.15 0.5</size>
            </box>
          </geometry>
          <material>
            <script>
              <uri>file://media/materials/scripts/gazebo.material</uri>
              <name>Gazebo/Wood</name>
            </script>
            <ambient>0.996078 0.47451 0.0196078 1</ambient>
          </material>
          <meta>
            <layer>0</layer>
          </meta>
        </visual>
        <collision name='Wall_8_Collision_1'>
          <geometry>
            <box>
              <size>3.00955 0.15 0.5</size>
            </box>
          </geometry>
          <pose>0.745225 0 0.25 0 -0 0</pose>
          <max_contacts>10</max_contacts>
          <surface>
            <contact>
              <ode/>
            </contact>
            <bounce/>
            <friction>
              <torsional>
                <ode/>
              </torsional>
              <ode/>
            </friction>
          </surface>
        </collision>
        <visual name='Wall_8_Visual_2'>
          <pose>1.14522 0 1.5 0 -0 0</pose>
          <geometry>
            <box>
              <size>2.20955 0.15 2</size>
            </box>
          </geometry>
          <material>
            <script>
              <uri>file://media/materials/scripts/gazebo.material</uri>
              <name>Gazebo/Wood</name>
            </script>
            <ambient>0.996078 0.47451 0.0196078 1</ambient>
          </material>
          <meta>
            <layer>0</layer>
          </meta>
        </visual>
        <collision name='Wall_8_Collision_2'>
          <geometry>
            <box>
              <size>2.20955 0.15 2</size>
            </box>
          </geometry>
          <pose>1.14522 0 1.5 0 -0 0</pose>
          <max_contacts>10</max_contacts>
          <surface>
            <contact>
              <ode/>
            </contact>
            <bounce/>
            <friction>
              <torsional>
                <ode/>
              </torsional>
              <ode/>
            </friction>
          </surface>
        </collision>
        <visual name='Wall_8_Visual_3'>
          <pose>-0.35955 0 1.9 0 -0 0</pose>
          <geometry>
            <box>
              <size>0.8 0.15 1.2</size>
            </box>
          </geometry>
          <material>
            <script>
              <uri>file://media/materials/scripts/gazebo.material</uri>
              <name>Gazebo/Wood</name>
            </script>
            <ambient>0.996078 0.47451 0.0196078 1</ambient>
          </material>
          <meta>
            <layer>0</layer>
          </meta>
        </visual>
        <collision name='Wall_8_Collision_3'>
          <geometry>
            <box>
              <size>0.8 0.15 1.2</size>
            </box>
          </geometry>
          <pose>-0.35955 0 1.9 0 -0 0</pose>
          <max_contacts>10</max_contacts>
          <surface>
            <contact>
              <ode/>
            </contact>
            <bounce/>
            <friction>
              <torsional>
                <ode/>
              </torsional>
              <ode/>
            </friction>
          </surface>
        </collision>
        <self_collide>0</self_collide>
        <enable_wind>0</enable_wind>
        <kinematic>0</kinematic>
      </link>
      <static>1</static>
    </model>
    <model name='model_0_clone'>
      <link name='link_0'>
        <inertial>
          <mass>1</mass>
          <inertia>
            <ixx>0.166667</ixx>
            <ixy>0</ixy>
            <ixz>0</ixz>
            <iyy>0.166667</iyy>
            <iyz>0</iyz>
            <izz>0.166667</izz>
          </inertia>
          <pose>0 0 0 0 -0 0</pose>
        </inertial>
        <pose>0.008 0.004 0.692007 0 -0 0</pose>
        <gravity>1</gravity>
        <self_collide>0</self_collide>
        <kinematic>0</kinematic>
        <enable_wind>0</enable_wind>
        <visual name='visual'>
          <pose>0 0 0 0 -0 0</pose>
          <geometry>
            <box>
              <size>1 1 0.1</size>
            </box>
          </geometry>
          <material>
            <lighting>1</lighting>
            <script>
              <uri>file://media/materials/scripts/gazebo.material</uri>
              <name>Gazebo/Grey</name>
            </script>
            <shader type='pixel'>
              <normal_map>__default__</normal_map>
            </shader>
            <ambient>0.3 0.3 0.3 1</ambient>
            <diffuse>0.7 0.7 0.7 1</diffuse>
            <specular>0.01 0.01 0.01 1</specular>
            <emissive>0 0 0 1</emissive>
          </material>
          <transparency>0</transparency>
          <cast_shadows>1</cast_shadows>
        </visual>
        <collision name='collision'>
          <laser_retro>0</laser_retro>
          <max_contacts>10</max_contacts>
          <pose>0 0 0 0 -0 0</pose>
          <geometry>
            <box>
              <size>1 1 0.1</size>
            </box>
          </geometry>
          <surface>
            <friction>
              <ode>
                <mu>1</mu>
                <mu2>1</mu2>
                <fdir1>0 0 0</fdir1>
                <slip1>0</slip1>
                <slip2>0</slip2>
              </ode>
              <torsional>
                <coefficient>1</coefficient>
                <patch_radius>0</patch_radius>
                <surface_radius>0</surface_radius>
                <use_patch_radius>1</use_patch_radius>
                <ode>
                  <slip>0</slip>
                </ode>
              </torsional>
            </friction>
            <bounce>
              <restitution_coefficient>0</restitution_coefficient>
              <threshold>1e+06</threshold>
            </bounce>
            <contact>
              <collide_without_contact>0</collide_without_contact>
              <collide_without_contact_bitmask>1</collide_without_contact_bitmask>
              <collide_bitmask>1</collide_bitmask>
              <ode>
                <soft_cfm>0</soft_cfm>
                <soft_erp>0.2</soft_erp>
                <kp>1e+13</kp>
                <kd>1</kd>
                <max_vel>0.01</max_vel>
                <min_depth>0</min_depth>
              </ode>
              <bullet>
                <split_impulse>1</split_impulse>
                <split_impulse_penetration_threshold>-0.01</split_impulse_penetration_threshold>
                <soft_cfm>0</soft_cfm>
                <soft_erp>0.2</soft_erp>
                <kp>1e+13</kp>
                <kd>1</kd>
              </bullet>
            </contact>
          </surface>
        </collision>
      </link>
      <link name='link_1'>
        <inertial>
          <mass>1</mass>
          <inertia>
            <ixx>0.145833</ixx>
            <ixy>0</ixy>
            <ixz>0</ixz>
            <iyy>0.145833</iyy>
            <iyz>0</iyz>
            <izz>0.125</izz>
          </inertia>
          <pose>0 0 0 0 -0 0</pose>
        </inertial>
        <pose>-0.012 -0.016 0.142007 0 -0 0</pose>
        <gravity>1</gravity>
        <self_collide>0</self_collide>
        <kinematic>0</kinematic>
        <enable_wind>0</enable_wind>
        <visual name='visual'>
          <pose>0 0 0 0 -0 0</pose>
          <geometry>
            <cylinder>
              <radius>0.1</radius>
              <length>1</length>
            </cylinder>
          </geometry>
          <material>
            <lighting>1</lighting>
            <script>
              <uri>file://media/materials/scripts/gazebo.material</uri>
              <name>Gazebo/Grey</name>
            </script>
            <shader type='pixel'>
              <normal_map>__default__</normal_map>
            </shader>
            <ambient>0.3 0.3 0.3 1</ambient>
            <diffuse>0.7 0.7 0.7 1</diffuse>
            <specular>0.01 0.01 0.01 1</specular>
            <emissive>0 0 0 1</emissive>
          </material>
          <transparency>0</transparency>
          <cast_shadows>1</cast_shadows>
        </visual>
        <collision name='collision'>
          <laser_retro>0</laser_retro>
          <max_contacts>10</max_contacts>
          <pose>0 0 0 0 -0 0</pose>
          <geometry>
            <cylinder>
              <radius>0.1</radius>
              <length>1</length>
            </cylinder>
          </geometry>
          <surface>
            <friction>
              <ode>
                <mu>1</mu>
                <mu2>1</mu2>
                <fdir1>0 0 0</fdir1>
                <slip1>0</slip1>
                <slip2>0</slip2>
              </ode>
              <torsional>
                <coefficient>1</coefficient>
                <patch_radius>0</patch_radius>
                <surface_radius>0</surface_radius>
                <use_patch_radius>1</use_patch_radius>
                <ode>
                  <slip>0</slip>
                </ode>
              </torsional>
            </friction>
            <bounce>
              <restitution_coefficient>0</restitution_coefficient>
              <threshold>1e+06</threshold>
            </bounce>
            <contact>
              <collide_without_contact>0</collide_without_contact>
              <collide_without_contact_bitmask>1</collide_without_contact_bitmask>
              <collide_bitmask>1</collide_bitmask>
              <ode>
                <soft_cfm>0</soft_cfm>
                <soft_erp>0.2</soft_erp>
                <kp>1e+13</kp>
                <kd>1</kd>
                <max_vel>0.01</max_vel>
                <min_depth>0</min_depth>
              </ode>
              <bullet>
                <split_impulse>1</split_impulse>
                <split_impulse_penetration_threshold>-0.01</split_impulse_penetration_threshold>
                <soft_cfm>0</soft_cfm>
                <soft_erp>0.2</soft_erp>
                <kp>1e+13</kp>
                <kd>1</kd>
              </bullet>
            </contact>
          </surface>
        </collision>
      </link>
      <link name='link_2'>
        <inertial>
          <mass>1</mass>
          <inertia>
            <ixx>0.166667</ixx>
            <ixy>0</ixy>
            <ixz>0</ixz>
            <iyy>0.166667</iyy>
            <iyz>0</iyz>
            <izz>0.166667</izz>
          </inertia>
          <pose>0 0 0 0 -0 0</pose>
        </inertial>
        <pose>-0.012 0.004 -0.307993 0 -0 0</pose>
        <gravity>1</gravity>
        <self_collide>0</self_collide>
        <kinematic>0</kinematic>
        <enable_wind>0</enable_wind>
        <visual name='visual'>
          <pose>0 0 0 0 -0 0</pose>
          <geometry>
            <box>
              <size>0.2 1 0.1</size>
            </box>
          </geometry>
          <material>
            <lighting>1</lighting>
            <script>
              <uri>file://media/materials/scripts/gazebo.material</uri>
              <name>Gazebo/Grey</name>
            </script>
            <shader type='pixel'>
              <normal_map>__default__</normal_map>
            </shader>
            <ambient>0.3 0.3 0.3 1</ambient>
            <diffuse>0.7 0.7 0.7 1</diffuse>
            <specular>0.01 0.01 0.01 1</specular>
            <emissive>0 0 0 1</emissive>
          </material>
          <transparency>0</transparency>
          <cast_shadows>1</cast_shadows>
        </visual>
        <collision name='collision'>
          <laser_retro>0</laser_retro>
          <max_contacts>10</max_contacts>
          <pose>0 0 0 0 -0 0</pose>
          <geometry>
            <box>
              <size>0.2 1 0.1</size>
            </box>
          </geometry>
          <surface>
            <friction>
              <ode>
                <mu>1</mu>
                <mu2>1</mu2>
                <fdir1>0 0 0</fdir1>
                <slip1>0</slip1>
                <slip2>0</slip2>
              </ode>
              <torsional>
                <coefficient>1</coefficient>
                <patch_radius>0</patch_radius>
                <surface_radius>0</surface_radius>
                <use_patch_radius>1</use_patch_radius>
                <ode>
                  <slip>0</slip>
                </ode>
              </torsional>
            </friction>
            <bounce>
              <restitution_coefficient>0</restitution_coefficient>
              <threshold>1e+06</threshold>
            </bounce>
            <contact>
              <collide_without_contact>0</collide_without_contact>
              <collide_without_contact_bitmask>1</collide_without_contact_bitmask>
              <collide_bitmask>1</collide_bitmask>
              <ode>
                <soft_cfm>0</soft_cfm>
                <soft_erp>0.2</soft_erp>
                <kp>1e+13</kp>
                <kd>1</kd>
                <max_vel>0.01</max_vel>
                <min_depth>0</min_depth>
              </ode>
              <bullet>
                <split_impulse>1</split_impulse>
                <split_impulse_penetration_threshold>-0.01</split_impulse_penetration_threshold>
                <soft_cfm>0</soft_cfm>
                <soft_erp>0.2</soft_erp>
                <kp>1e+13</kp>
                <kd>1</kd>
              </bullet>
            </contact>
          </surface>
        </collision>
      </link>
      <link name='link_3'>
        <inertial>
          <mass>1</mass>
          <inertia>
            <ixx>0.145833</ixx>
            <ixy>0</ixy>
            <ixz>0</ixz>
            <iyy>0.145833</iyy>
            <iyz>0</iyz>
            <izz>0.125</izz>
          </inertia>
          <pose>0 0 0 1.57 -0 0</pose>
        </inertial>
        <pose>0.008 -0.546159 -0.263029 1.57 -0 0</pose>
        <gravity>1</gravity>
        <self_collide>0</self_collide>
        <kinematic>0</kinematic>
        <enable_wind>0</enable_wind>
        <visual name='visual'>
          <pose>0 0 0 0 -0 0</pose>
          <geometry>
            <cylinder>
              <radius>0.2</radius>
              <length>0.1</length>
            </cylinder>
          </geometry>
          <material>
            <lighting>1</lighting>
            <script>
              <uri>file://media/materials/scripts/gazebo.material</uri>
              <name>Gazebo/Grey</name>
            </script>
            <shader type='pixel'>
              <normal_map>__default__</normal_map>
            </shader>
            <ambient>0.3 0.3 0.3 1</ambient>
            <diffuse>0.7 0.7 0.7 1</diffuse>
            <specular>0.01 0.01 0.01 1</specular>
            <emissive>0 0 0 1</emissive>
          </material>
          <transparency>0</transparency>
          <cast_shadows>1</cast_shadows>
        </visual>
        <collision name='collision'>
          <laser_retro>0</laser_retro>
          <max_contacts>10</max_contacts>
          <pose>0 0 0 0 -0 0</pose>
          <geometry>
            <cylinder>
              <radius>0.2</radius>
              <length>0.1</length>
            </cylinder>
          </geometry>
          <surface>
            <friction>
              <ode>
                <mu>1</mu>
                <mu2>1</mu2>
                <fdir1>0 0 0</fdir1>
                <slip1>0</slip1>
                <slip2>0</slip2>
              </ode>
              <torsional>
                <coefficient>1</coefficient>
                <patch_radius>0</patch_radius>
                <surface_radius>0</surface_radius>
                <use_patch_radius>1</use_patch_radius>
                <ode>
                  <slip>0</slip>
                </ode>
              </torsional>
            </friction>
            <bounce>
              <restitution_coefficient>0</restitution_coefficient>
              <threshold>1e+06</threshold>
            </bounce>
            <contact>
              <collide_without_contact>0</collide_without_contact>
              <collide_without_contact_bitmask>1</collide_without_contact_bitmask>
              <collide_bitmask>1</collide_bitmask>
              <ode>
                <soft_cfm>0</soft_cfm>
                <soft_erp>0.2</soft_erp>
                <kp>1e+13</kp>
                <kd>1</kd>
                <max_vel>0.01</max_vel>
                <min_depth>0</min_depth>
              </ode>
              <bullet>
                <split_impulse>1</split_impulse>
                <split_impulse_penetration_threshold>-0.01</split_impulse_penetration_threshold>
                <soft_cfm>0</soft_cfm>
                <soft_erp>0.2</soft_erp>
                <kp>1e+13</kp>
                <kd>1</kd>
              </bullet>
            </contact>
          </surface>
        </collision>
      </link>
      <link name='link_3_clone'>
        <inertial>
          <mass>1</mass>
          <inertia>
            <ixx>0.145833</ixx>
            <ixy>0</ixy>
            <ixz>0</ixz>
            <iyy>0.145833</iyy>
            <iyz>0</iyz>
            <izz>0.125</izz>
          </inertia>
          <pose>0 0 0 0 -0 0</pose>
        </inertial>
        <pose>0.008 0.554159 -0.262993 1.57 -0 0</pose>
        <gravity>1</gravity>
        <self_collide>0</self_collide>
        <kinematic>0</kinematic>
        <enable_wind>0</enable_wind>
        <visual name='visual'>
          <pose>0 0 0 0 -0 0</pose>
          <geometry>
            <cylinder>
              <radius>0.2</radius>
              <length>0.1</length>
            </cylinder>
          </geometry>
          <material>
            <lighting>1</lighting>
            <script>
              <uri>file://media/materials/scripts/gazebo.material</uri>
              <name>Gazebo/Grey</name>
            </script>
            <shader type='pixel'>
              <normal_map>__default__</normal_map>
            </shader>
            <ambient>0.3 0.3 0.3 1</ambient>
            <diffuse>0.7 0.7 0.7 1</diffuse>
            <specular>0.01 0.01 0.01 1</specular>
            <emissive>0 0 0 1</emissive>
          </material>
          <transparency>0</transparency>
          <cast_shadows>1</cast_shadows>
        </visual>
        <collision name='collision'>
          <laser_retro>0</laser_retro>
          <max_contacts>10</max_contacts>
          <pose>0 0 0 0 -0 0</pose>
          <geometry>
            <cylinder>
              <radius>0.2</radius>
              <length>0.1</length>
            </cylinder>
          </geometry>
          <surface>
            <friction>
              <ode>
                <mu>1</mu>
                <mu2>1</mu2>
                <fdir1>0 0 0</fdir1>
                <slip1>0</slip1>
                <slip2>0</slip2>
              </ode>
              <torsional>
                <coefficient>1</coefficient>
                <patch_radius>0</patch_radius>
                <surface_radius>0</surface_radius>
                <use_patch_radius>1</use_patch_radius>
                <ode>
                  <slip>0</slip>
                </ode>
              </torsional>
            </friction>
            <bounce>
              <restitution_coefficient>0</restitution_coefficient>
              <threshold>1e+06</threshold>
            </bounce>
            <contact>
              <collide_without_contact>0</collide_without_contact>
              <collide_without_contact_bitmask>1</collide_without_contact_bitmask>
              <collide_bitmask>1</collide_bitmask>
              <ode>
                <soft_cfm>0</soft_cfm>
                <soft_erp>0.2</soft_erp>
                <kp>1e+13</kp>
                <kd>1</kd>
                <max_vel>0.01</max_vel>
                <min_depth>0</min_depth>
              </ode>
              <bullet>
                <split_impulse>1</split_impulse>
                <split_impulse_penetration_threshold>-0.01</split_impulse_penetration_threshold>
                <soft_cfm>0</soft_cfm>
                <soft_erp>0.2</soft_erp>
                <kp>1e+13</kp>
                <kd>1</kd>
              </bullet>
            </contact>
          </surface>
        </collision>
      </link>
      <joint name='link_0_JOINT_0' type='fixed'>
        <parent>link_0</parent>
        <child>link_1</child>
        <pose>0 0 0 0 -0.01 0</pose>
        <physics>
          <ode>
            <limit>
              <cfm>0</cfm>
              <erp>0.2</erp>
            </limit>
            <suspension>
              <cfm>0</cfm>
              <erp>0.2</erp>
            </suspension>
          </ode>
        </physics>
      </joint>
      <joint name='link_1_JOINT_1' type='fixed'>
        <parent>link_1</parent>
        <child>link_2</child>
        <pose>0 0 0 0 -0 0</pose>
        <physics>
          <ode>
            <limit>
              <cfm>0</cfm>
              <erp>0.2</erp>
            </limit>
            <suspension>
              <cfm>0</cfm>
              <erp>0.2</erp>
            </suspension>
          </ode>
        </physics>
      </joint>
      <joint name='link_2_JOINT_3' type='revolute'>
        <parent>link_2</parent>
        <child>link_3</child>
        <pose>0 0 0 0 -0 0</pose>
        <axis>
          <xyz>0 0 1</xyz>
          <limit>
            <lower>-1.79769e+308</lower>
            <upper>1.79769e+308</upper>
            <effort>-1</effort>
            <velocity>-1</velocity>
          </limit>
          <dynamics>
            <spring_reference>0</spring_reference>
            <spring_stiffness>0</spring_stiffness>
            <damping>0</damping>
          </dynamics>
        </axis>
        <physics>
          <ode>
            <limit>
              <cfm>0</cfm>
              <erp>0.2</erp>
            </limit>
            <suspension>
              <cfm>0</cfm>
              <erp>0.2</erp>
            </suspension>
          </ode>
        </physics>
      </joint>
      <joint name='link_2_JOINT_4' type='revolute'>
        <parent>link_2</parent>
        <child>link_3_clone</child>
        <pose>0 0 0 0 -0 0</pose>
        <axis>
          <xyz>0 0 1</xyz>
          <limit>
            <lower>-1.79769e+308</lower>
            <upper>1.79769e+308</upper>
            <effort>-1</effort>
            <velocity>-1</velocity>
          </limit>
          <dynamics>
            <spring_reference>0</spring_reference>
            <spring_stiffness>0</spring_stiffness>
            <damping>0</damping>
          </dynamics>
        </axis>
        <physics>
          <ode>
            <limit>
              <cfm>0</cfm>
              <erp>0.2</erp>
            </limit>
            <suspension>
              <cfm>0</cfm>
              <erp>0.2</erp>
            </suspension>
          </ode>
        </physics>
      </joint>
      <static>0</static>
      <allow_auto_disable>1</allow_auto_disable>
      <pose>5.68439 -3.74617 0.474522 0 -0 0</pose>
    </model>
    <model name='cafe_table'>
      <static>1</static>
      <link name='link'>
        <collision name='surface'>
          <pose>0 0 0.755 0 -0 0</pose>
          <geometry>
            <box>
              <size>0.913 0.913 0.04</size>
            </box>
          </geometry>
          <max_contacts>10</max_contacts>
          <surface>
            <contact>
              <ode/>
            </contact>
            <bounce/>
            <friction>
              <torsional>
                <ode/>
              </torsional>
              <ode/>
            </friction>
          </surface>
        </collision>
        <collision name='column'>
          <pose>0 0 0.37 0 -0 0</pose>
          <geometry>
            <box>
              <size>0.042 0.042 0.74</size>
            </box>
          </geometry>
          <max_contacts>10</max_contacts>
          <surface>
            <contact>
              <ode/>
            </contact>
            <bounce/>
            <friction>
              <torsional>
                <ode/>
              </torsional>
              <ode/>
            </friction>
          </surface>
        </collision>
        <collision name='base'>
          <pose>0 0 0.02 0 -0 0</pose>
          <geometry>
            <box>
              <size>0.56 0.56 0.04</size>
            </box>
          </geometry>
          <max_contacts>10</max_contacts>
          <surface>
            <contact>
              <ode/>
            </contact>
            <bounce/>
            <friction>
              <torsional>
                <ode/>
              </torsional>
              <ode/>
            </friction>
          </surface>
        </collision>
        <visual name='visual'>
          <geometry>
            <mesh>
              <uri>model://cafe_table/meshes/cafe_table.dae</uri>
            </mesh>
          </geometry>
        </visual>
        <self_collide>0</self_collide>
        <enable_wind>0</enable_wind>
        <kinematic>0</kinematic>
      </link>
      <pose>5.37115 -2.01626 0 0 -0 0</pose>
    </model>
    <model name='ball_valve_wall'>
      <frame name='wall::__model__' attached_to='wall::link'>
        <pose relative_to='__model__'>0 0 0 0 -0 0</pose>
      </frame>
      <link name='wall::link'>
        <inertial>
          <pose>0.6096 0.00476 1.2192 0 -0 0</pose>
          <mass>2.5</mass>
          <inertia>
            <ixx>1.23873</ixx>
            <ixy>0</ixy>
            <ixz>0</ixz>
            <iyy>1.54838</iyy>
            <iyz>0</iyz>
            <izz>0.309696</izz>
          </inertia>
        </inertial>
        <collision name='collision'>
          <pose>0.6096 0.00476 1.2192 0 -0 0</pose>
          <geometry>
            <box>
              <size>1.2192 0.00952 2.4384</size>
            </box>
          </geometry>
          <max_contacts>10</max_contacts>
          <surface>
            <contact>
              <ode/>
            </contact>
            <bounce/>
            <friction>
              <torsional>
                <ode/>
              </torsional>
              <ode/>
            </friction>
          </surface>
        </collision>
        <visual name='visual'>
          <pose>-0.004536 -0.003572 0 0 -0 0</pose>
          <geometry>
            <mesh>
              <uri>model://drc_practice_valve_wall/meshes/five_dice_wall.dae</uri>
            </mesh>
          </geometry>
        </visual>
        <pose relative_to='wall::__model__'>0 0 0 0 -0 0</pose>
        <self_collide>0</self_collide>
        <enable_wind>0</enable_wind>
        <kinematic>0</kinematic>
      </link>
      <static>0</static>
      <joint name='wall-joint' type='revolute'>
        <parent>world</parent>
        <child>wall::link</child>
        <axis>
          <xyz expressed_in='__model__'>0 0 1</xyz>
          <limit>
            <lower>0</lower>
            <upper>0</upper>
          </limit>
          <dynamics>
            <spring_reference>0</spring_reference>
            <spring_stiffness>0</spring_stiffness>
          </dynamics>
        </axis>
      </joint>
      <frame name='valve_0::__model__' attached_to='valve_0::handle'>
        <pose relative_to='__model__'>0.919587 -0.0092 0.285 0 -0 0</pose>
      </frame>
      <link name='valve_0::handle'>
        <pose relative_to='valve_0::__model__'>0 0.0275 0.02222 1.57079 9.3e-05 3.14159</pose>
        <inertial>
          <mass>0.0802</mass>
          <pose>0 0.0435 0.0055 0 -0 0</pose>
          <inertia>
            <ixx>3.8e-05</ixx>
            <iyy>4e-06</iyy>
            <izz>4e-05</izz>
            <ixy>0</ixy>
            <ixz>0</ixz>
            <iyz>0</iyz>
          </inertia>
        </inertial>
        <collision name='collision'>
          <geometry>
            <mesh>
              <uri>model://drc_practice_ball_valve/meshes/ball_valve.dae</uri>
            </mesh>
          </geometry>
          <surface>
            <bounce>
              <restitution_coefficient>0.01</restitution_coefficient>
              <threshold>5</threshold>
            </bounce>
            <friction>
              <ode>
                <mu>5</mu>
                <mu2>5</mu2>
              </ode>
              <torsional>
                <ode/>
              </torsional>
            </friction>
            <contact>
              <ode>
                <soft_cfm>0.01</soft_cfm>
                <kp>10000</kp>
                <kd>1000</kd>
                <max_vel>0.01</max_vel>
                <min_depth>0.001</min_depth>
              </ode>
            </contact>
          </surface>
          <max_contacts>10</max_contacts>
        </collision>
        <visual name='visual'>
          <geometry>
            <mesh>
              <uri>model://drc_practice_ball_valve/meshes/ball_valve.dae</uri>
            </mesh>
          </geometry>
        </visual>
        <self_collide>0</self_collide>
        <enable_wind>0</enable_wind>
        <kinematic>0</kinematic>
      </link>
      <joint name='valve_0::ball' type='revolute'>
        <parent>world</parent>
        <child>valve_0::handle</child>
        <axis>
          <xyz expressed_in='valve_0::__model__'>0 1 0</xyz>
          <limit>
            <lower>0</lower>
            <upper>1.58</upper>
          </limit>
          <dynamics>
            <damping>0.3</damping>
            <friction>10</friction>
            <spring_reference>0</spring_reference>
            <spring_stiffness>0</spring_stiffness>
          </dynamics>
        </axis>
        <physics>
          <ode>
            <cfm_damping>1</cfm_damping>
            <limit>
              <cfm>0</cfm>
              <erp>0.2</erp>
            </limit>
          </ode>
        </physics>
      </joint>
      <frame name='valve_1::__model__' attached_to='valve_1::handle'>
        <pose relative_to='__model__'>0.919587 -0.0092 0.8954 0 -0 0</pose>
      </frame>
      <link name='valve_1::handle'>
        <pose relative_to='valve_1::__model__'>0 0.0275 0.02222 1.57079 9.3e-05 3.14159</pose>
        <inertial>
          <mass>0.0802</mass>
          <pose>0 0.0435 0.0055 0 -0 0</pose>
          <inertia>
            <ixx>3.8e-05</ixx>
            <iyy>4e-06</iyy>
            <izz>4e-05</izz>
            <ixy>0</ixy>
            <ixz>0</ixz>
            <iyz>0</iyz>
          </inertia>
        </inertial>
        <collision name='collision'>
          <geometry>
            <mesh>
              <uri>model://drc_practice_ball_valve/meshes/ball_valve.dae</uri>
            </mesh>
          </geometry>
          <surface>
            <bounce>
              <restitution_coefficient>0.01</restitution_coefficient>
              <threshold>5</threshold>
            </bounce>
            <friction>
              <ode>
                <mu>5</mu>
                <mu2>5</mu2>
              </ode>
              <torsional>
                <ode/>
              </torsional>
            </friction>
            <contact>
              <ode>
                <soft_cfm>0.01</soft_cfm>
                <kp>10000</kp>
                <kd>1000</kd>
                <max_vel>0.01</max_vel>
                <min_depth>0.001</min_depth>
              </ode>
            </contact>
          </surface>
          <max_contacts>10</max_contacts>
        </collision>
        <visual name='visual'>
          <geometry>
            <mesh>
              <uri>model://drc_practice_ball_valve/meshes/ball_valve.dae</uri>
            </mesh>
          </geometry>
        </visual>
        <self_collide>0</self_collide>
        <enable_wind>0</enable_wind>
        <kinematic>0</kinematic>
      </link>
      <joint name='valve_1::ball' type='revolute'>
        <parent>world</parent>
        <child>valve_1::handle</child>
        <axis>
          <xyz expressed_in='valve_1::__model__'>0 1 0</xyz>
          <limit>
            <lower>0</lower>
            <upper>1.58</upper>
          </limit>
          <dynamics>
            <damping>0.3</damping>
            <friction>10</friction>
            <spring_reference>0</spring_reference>
            <spring_stiffness>0</spring_stiffness>
          </dynamics>
        </axis>
        <physics>
          <ode>
            <cfm_damping>1</cfm_damping>
            <limit>
              <cfm>0</cfm>
              <erp>0.2</erp>
            </limit>
          </ode>
        </physics>
      </joint>
      <frame name='valve_2::__model__' attached_to='valve_2::handle'>
        <pose relative_to='__model__'>0.919587 -0.0092 1.5058 0 -0 0</pose>
      </frame>
      <link name='valve_2::handle'>
        <pose relative_to='valve_2::__model__'>0 0.0275 0.02222 1.57079 9.3e-05 3.14159</pose>
        <inertial>
          <mass>0.0802</mass>
          <pose>0 0.0435 0.0055 0 -0 0</pose>
          <inertia>
            <ixx>3.8e-05</ixx>
            <iyy>4e-06</iyy>
            <izz>4e-05</izz>
            <ixy>0</ixy>
            <ixz>0</ixz>
            <iyz>0</iyz>
          </inertia>
        </inertial>
        <collision name='collision'>
          <geometry>
            <mesh>
              <uri>model://drc_practice_ball_valve/meshes/ball_valve.dae</uri>
            </mesh>
          </geometry>
          <surface>
            <bounce>
              <restitution_coefficient>0.01</restitution_coefficient>
              <threshold>5</threshold>
            </bounce>
            <friction>
              <ode>
                <mu>5</mu>
                <mu2>5</mu2>
              </ode>
              <torsional>
                <ode/>
              </torsional>
            </friction>
            <contact>
              <ode>
                <soft_cfm>0.01</soft_cfm>
                <kp>10000</kp>
                <kd>1000</kd>
                <max_vel>0.01</max_vel>
                <min_depth>0.001</min_depth>
              </ode>
            </contact>
          </surface>
          <max_contacts>10</max_contacts>
        </collision>
        <visual name='visual'>
          <geometry>
            <mesh>
              <uri>model://drc_practice_ball_valve/meshes/ball_valve.dae</uri>
            </mesh>
          </geometry>
        </visual>
        <self_collide>0</self_collide>
        <enable_wind>0</enable_wind>
        <kinematic>0</kinematic>
      </link>
      <joint name='valve_2::ball' type='revolute'>
        <parent>world</parent>
        <child>valve_2::handle</child>
        <axis>
          <xyz expressed_in='valve_2::__model__'>0 1 0</xyz>
          <limit>
            <lower>0</lower>
            <upper>1.58</upper>
          </limit>
          <dynamics>
            <damping>0.3</damping>
            <friction>10</friction>
            <spring_reference>0</spring_reference>
            <spring_stiffness>0</spring_stiffness>
          </dynamics>
        </axis>
        <physics>
          <ode>
            <cfm_damping>1</cfm_damping>
            <limit>
              <cfm>0</cfm>
              <erp>0.2</erp>
            </limit>
          </ode>
        </physics>
      </joint>
      <frame name='valve_3::__model__' attached_to='valve_3::handle'>
        <pose relative_to='__model__'>0.919587 -0.0092 2.1162 0 -0 0</pose>
      </frame>
      <link name='valve_3::handle'>
        <pose relative_to='valve_3::__model__'>0 0.0275 0.02222 1.57079 9.3e-05 3.14159</pose>
        <inertial>
          <mass>0.0802</mass>
          <pose>0 0.0435 0.0055 0 -0 0</pose>
          <inertia>
            <ixx>3.8e-05</ixx>
            <iyy>4e-06</iyy>
            <izz>4e-05</izz>
            <ixy>0</ixy>
            <ixz>0</ixz>
            <iyz>0</iyz>
          </inertia>
        </inertial>
        <collision name='collision'>
          <geometry>
            <mesh>
              <uri>model://drc_practice_ball_valve/meshes/ball_valve.dae</uri>
            </mesh>
          </geometry>
          <surface>
            <bounce>
              <restitution_coefficient>0.01</restitution_coefficient>
              <threshold>5</threshold>
            </bounce>
            <friction>
              <ode>
                <mu>5</mu>
                <mu2>5</mu2>
              </ode>
              <torsional>
                <ode/>
              </torsional>
            </friction>
            <contact>
              <ode>
                <soft_cfm>0.01</soft_cfm>
                <kp>10000</kp>
                <kd>1000</kd>
                <max_vel>0.01</max_vel>
                <min_depth>0.001</min_depth>
              </ode>
            </contact>
          </surface>
          <max_contacts>10</max_contacts>
        </collision>
        <visual name='visual'>
          <geometry>
            <mesh>
              <uri>model://drc_practice_ball_valve/meshes/ball_valve.dae</uri>
            </mesh>
          </geometry>
        </visual>
        <self_collide>0</self_collide>
        <enable_wind>0</enable_wind>
        <kinematic>0</kinematic>
      </link>
      <joint name='valve_3::ball' type='revolute'>
        <parent>world</parent>
        <child>valve_3::handle</child>
        <axis>
          <xyz expressed_in='valve_3::__model__'>0 1 0</xyz>
          <limit>
            <lower>0</lower>
            <upper>1.58</upper>
          </limit>
          <dynamics>
            <damping>0.3</damping>
            <friction>10</friction>
            <spring_reference>0</spring_reference>
            <spring_stiffness>0</spring_stiffness>
          </dynamics>
        </axis>
        <physics>
          <ode>
            <cfm_damping>1</cfm_damping>
            <limit>
              <cfm>0</cfm>
              <erp>0.2</erp>
            </limit>
          </ode>
        </physics>
      </joint>
      <frame name='valve_4::__model__' attached_to='valve_4::handle'>
        <pose relative_to='__model__'>0.614335 -0.0092 0.5896 0 -0 0</pose>
      </frame>
      <link name='valve_4::handle'>
        <pose relative_to='valve_4::__model__'>0 0.0275 0.02222 1.57079 9.3e-05 3.14159</pose>
        <inertial>
          <mass>0.0802</mass>
          <pose>0 0.0435 0.0055 0 -0 0</pose>
          <inertia>
            <ixx>3.8e-05</ixx>
            <iyy>4e-06</iyy>
            <izz>4e-05</izz>
            <ixy>0</ixy>
            <ixz>0</ixz>
            <iyz>0</iyz>
          </inertia>
        </inertial>
        <collision name='collision'>
          <geometry>
            <mesh>
              <uri>model://drc_practice_ball_valve/meshes/ball_valve.dae</uri>
            </mesh>
          </geometry>
          <surface>
            <bounce>
              <restitution_coefficient>0.01</restitution_coefficient>
              <threshold>5</threshold>
            </bounce>
            <friction>
              <ode>
                <mu>5</mu>
                <mu2>5</mu2>
              </ode>
              <torsional>
                <ode/>
              </torsional>
            </friction>
            <contact>
              <ode>
                <soft_cfm>0.01</soft_cfm>
                <kp>10000</kp>
                <kd>1000</kd>
                <max_vel>0.01</max_vel>
                <min_depth>0.001</min_depth>
              </ode>
            </contact>
          </surface>
          <max_contacts>10</max_contacts>
        </collision>
        <visual name='visual'>
          <geometry>
            <mesh>
              <uri>model://drc_practice_ball_valve/meshes/ball_valve.dae</uri>
            </mesh>
          </geometry>
        </visual>
        <self_collide>0</self_collide>
        <enable_wind>0</enable_wind>
        <kinematic>0</kinematic>
      </link>
      <joint name='valve_4::ball' type='revolute'>
        <parent>world</parent>
        <child>valve_4::handle</child>
        <axis>
          <xyz expressed_in='valve_4::__model__'>0 1 0</xyz>
          <limit>
            <lower>0</lower>
            <upper>1.58</upper>
          </limit>
          <dynamics>
            <damping>0.3</damping>
            <friction>10</friction>
            <spring_reference>0</spring_reference>
            <spring_stiffness>0</spring_stiffness>
          </dynamics>
        </axis>
        <physics>
          <ode>
            <cfm_damping>1</cfm_damping>
            <limit>
              <cfm>0</cfm>
              <erp>0.2</erp>
            </limit>
          </ode>
        </physics>
      </joint>
      <frame name='valve_5::__model__' attached_to='valve_5::handle'>
        <pose relative_to='__model__'>0.614335 -0.0092 1.2 0 -0 0</pose>
      </frame>
      <link name='valve_5::handle'>
        <pose relative_to='valve_5::__model__'>0 0.0275 0.02222 1.57079 9.3e-05 3.14159</pose>
        <inertial>
          <mass>0.0802</mass>
          <pose>0 0.0435 0.0055 0 -0 0</pose>
          <inertia>
            <ixx>3.8e-05</ixx>
            <iyy>4e-06</iyy>
            <izz>4e-05</izz>
            <ixy>0</ixy>
            <ixz>0</ixz>
            <iyz>0</iyz>
          </inertia>
        </inertial>
        <collision name='collision'>
          <geometry>
            <mesh>
              <uri>model://drc_practice_ball_valve/meshes/ball_valve.dae</uri>
            </mesh>
          </geometry>
          <surface>
            <bounce>
              <restitution_coefficient>0.01</restitution_coefficient>
              <threshold>5</threshold>
            </bounce>
            <friction>
              <ode>
                <mu>5</mu>
                <mu2>5</mu2>
              </ode>
              <torsional>
                <ode/>
              </torsional>
            </friction>
            <contact>
              <ode>
                <soft_cfm>0.01</soft_cfm>
                <kp>10000</kp>
                <kd>1000</kd>
                <max_vel>0.01</max_vel>
                <min_depth>0.001</min_depth>
              </ode>
            </contact>
          </surface>
          <max_contacts>10</max_contacts>
        </collision>
        <visual name='visual'>
          <geometry>
            <mesh>
              <uri>model://drc_practice_ball_valve/meshes/ball_valve.dae</uri>
            </mesh>
          </geometry>
        </visual>
        <self_collide>0</self_collide>
        <enable_wind>0</enable_wind>
        <kinematic>0</kinematic>
      </link>
      <joint name='valve_5::ball' type='revolute'>
        <parent>world</parent>
        <child>valve_5::handle</child>
        <axis>
          <xyz expressed_in='valve_5::__model__'>0 1 0</xyz>
          <limit>
            <lower>0</lower>
            <upper>1.58</upper>
          </limit>
          <dynamics>
            <damping>0.3</damping>
            <friction>10</friction>
            <spring_reference>0</spring_reference>
            <spring_stiffness>0</spring_stiffness>
          </dynamics>
        </axis>
        <physics>
          <ode>
            <cfm_damping>1</cfm_damping>
            <limit>
              <cfm>0</cfm>
              <erp>0.2</erp>
            </limit>
          </ode>
        </physics>
      </joint>
      <frame name='valve_6::__model__' attached_to='valve_6::handle'>
        <pose relative_to='__model__'>0.614335 -0.0092 1.8104 0 -0 0</pose>
      </frame>
      <link name='valve_6::handle'>
        <pose relative_to='valve_6::__model__'>0 0.0275 0.02222 1.57079 9.3e-05 3.14159</pose>
        <inertial>
          <mass>0.0802</mass>
          <pose>0 0.0435 0.0055 0 -0 0</pose>
          <inertia>
            <ixx>3.8e-05</ixx>
            <iyy>4e-06</iyy>
            <izz>4e-05</izz>
            <ixy>0</ixy>
            <ixz>0</ixz>
            <iyz>0</iyz>
          </inertia>
        </inertial>
        <collision name='collision'>
          <geometry>
            <mesh>
              <uri>model://drc_practice_ball_valve/meshes/ball_valve.dae</uri>
            </mesh>
          </geometry>
          <surface>
            <bounce>
              <restitution_coefficient>0.01</restitution_coefficient>
              <threshold>5</threshold>
            </bounce>
            <friction>
              <ode>
                <mu>5</mu>
                <mu2>5</mu2>
              </ode>
              <torsional>
                <ode/>
              </torsional>
            </friction>
            <contact>
              <ode>
                <soft_cfm>0.01</soft_cfm>
                <kp>10000</kp>
                <kd>1000</kd>
                <max_vel>0.01</max_vel>
                <min_depth>0.001</min_depth>
              </ode>
            </contact>
          </surface>
          <max_contacts>10</max_contacts>
        </collision>
        <visual name='visual'>
          <geometry>
            <mesh>
              <uri>model://drc_practice_ball_valve/meshes/ball_valve.dae</uri>
            </mesh>
          </geometry>
        </visual>
        <self_collide>0</self_collide>
        <enable_wind>0</enable_wind>
        <kinematic>0</kinematic>
      </link>
      <joint name='valve_6::ball' type='revolute'>
        <parent>world</parent>
        <child>valve_6::handle</child>
        <axis>
          <xyz expressed_in='valve_6::__model__'>0 1 0</xyz>
          <limit>
            <lower>0</lower>
            <upper>1.58</upper>
          </limit>
          <dynamics>
            <damping>0.3</damping>
            <friction>10</friction>
            <spring_reference>0</spring_reference>
            <spring_stiffness>0</spring_stiffness>
          </dynamics>
        </axis>
        <physics>
          <ode>
            <cfm_damping>1</cfm_damping>
            <limit>
              <cfm>0</cfm>
              <erp>0.2</erp>
            </limit>
          </ode>
        </physics>
      </joint>
      <frame name='valve_7::__model__' attached_to='valve_7::handle'>
        <pose relative_to='__model__'>0.309083 -0.0092 0.285 0 -0 0</pose>
      </frame>
      <link name='valve_7::handle'>
        <pose relative_to='valve_7::__model__'>0 0.0275 0.02222 1.57079 9.3e-05 3.14159</pose>
        <inertial>
          <mass>0.0802</mass>
          <pose>0 0.0435 0.0055 0 -0 0</pose>
          <inertia>
            <ixx>3.8e-05</ixx>
            <iyy>4e-06</iyy>
            <izz>4e-05</izz>
            <ixy>0</ixy>
            <ixz>0</ixz>
            <iyz>0</iyz>
          </inertia>
        </inertial>
        <collision name='collision'>
          <geometry>
            <mesh>
              <uri>model://drc_practice_ball_valve/meshes/ball_valve.dae</uri>
            </mesh>
          </geometry>
          <surface>
            <bounce>
              <restitution_coefficient>0.01</restitution_coefficient>
              <threshold>5</threshold>
            </bounce>
            <friction>
              <ode>
                <mu>5</mu>
                <mu2>5</mu2>
              </ode>
              <torsional>
                <ode/>
              </torsional>
            </friction>
            <contact>
              <ode>
                <soft_cfm>0.01</soft_cfm>
                <kp>10000</kp>
                <kd>1000</kd>
                <max_vel>0.01</max_vel>
                <min_depth>0.001</min_depth>
              </ode>
            </contact>
          </surface>
          <max_contacts>10</max_contacts>
        </collision>
        <visual name='visual'>
          <geometry>
            <mesh>
              <uri>model://drc_practice_ball_valve/meshes/ball_valve.dae</uri>
            </mesh>
          </geometry>
        </visual>
        <self_collide>0</self_collide>
        <enable_wind>0</enable_wind>
        <kinematic>0</kinematic>
      </link>
      <joint name='valve_7::ball' type='revolute'>
        <parent>world</parent>
        <child>valve_7::handle</child>
        <axis>
          <xyz expressed_in='valve_7::__model__'>0 1 0</xyz>
          <limit>
            <lower>0</lower>
            <upper>1.58</upper>
          </limit>
          <dynamics>
            <damping>0.3</damping>
            <friction>10</friction>
            <spring_reference>0</spring_reference>
            <spring_stiffness>0</spring_stiffness>
          </dynamics>
        </axis>
        <physics>
          <ode>
            <cfm_damping>1</cfm_damping>
            <limit>
              <cfm>0</cfm>
              <erp>0.2</erp>
            </limit>
          </ode>
        </physics>
      </joint>
      <frame name='valve_8::__model__' attached_to='valve_8::handle'>
        <pose relative_to='__model__'>0.309083 -0.0092 0.8954 0 -0 0</pose>
      </frame>
      <link name='valve_8::handle'>
        <pose relative_to='valve_8::__model__'>0 0.0275 0.02222 1.57079 9.3e-05 3.14159</pose>
        <inertial>
          <mass>0.0802</mass>
          <pose>0 0.0435 0.0055 0 -0 0</pose>
          <inertia>
            <ixx>3.8e-05</ixx>
            <iyy>4e-06</iyy>
            <izz>4e-05</izz>
            <ixy>0</ixy>
            <ixz>0</ixz>
            <iyz>0</iyz>
          </inertia>
        </inertial>
        <collision name='collision'>
          <geometry>
            <mesh>
              <uri>model://drc_practice_ball_valve/meshes/ball_valve.dae</uri>
            </mesh>
          </geometry>
          <surface>
            <bounce>
              <restitution_coefficient>0.01</restitution_coefficient>
              <threshold>5</threshold>
            </bounce>
            <friction>
              <ode>
                <mu>5</mu>
                <mu2>5</mu2>
              </ode>
              <torsional>
                <ode/>
              </torsional>
            </friction>
            <contact>
              <ode>
                <soft_cfm>0.01</soft_cfm>
                <kp>10000</kp>
                <kd>1000</kd>
                <max_vel>0.01</max_vel>
                <min_depth>0.001</min_depth>
              </ode>
            </contact>
          </surface>
          <max_contacts>10</max_contacts>
        </collision>
        <visual name='visual'>
          <geometry>
            <mesh>
              <uri>model://drc_practice_ball_valve/meshes/ball_valve.dae</uri>
            </mesh>
          </geometry>
        </visual>
        <self_collide>0</self_collide>
        <enable_wind>0</enable_wind>
        <kinematic>0</kinematic>
      </link>
      <joint name='valve_8::ball' type='revolute'>
        <parent>world</parent>
        <child>valve_8::handle</child>
        <axis>
          <xyz expressed_in='valve_8::__model__'>0 1 0</xyz>
          <limit>
            <lower>0</lower>
            <upper>1.58</upper>
          </limit>
          <dynamics>
            <damping>0.3</damping>
            <friction>10</friction>
            <spring_reference>0</spring_reference>
            <spring_stiffness>0</spring_stiffness>
          </dynamics>
        </axis>
        <physics>
          <ode>
            <cfm_damping>1</cfm_damping>
            <limit>
              <cfm>0</cfm>
              <erp>0.2</erp>
            </limit>
          </ode>
        </physics>
      </joint>
      <frame name='valve_9::__model__' attached_to='valve_9::handle'>
        <pose relative_to='__model__'>0.309083 -0.0092 1.5058 0 -0 0</pose>
      </frame>
      <link name='valve_9::handle'>
        <pose relative_to='valve_9::__model__'>0 0.0275 0.02222 1.57079 9.3e-05 3.14159</pose>
        <inertial>
          <mass>0.0802</mass>
          <pose>0 0.0435 0.0055 0 -0 0</pose>
          <inertia>
            <ixx>3.8e-05</ixx>
            <iyy>4e-06</iyy>
            <izz>4e-05</izz>
            <ixy>0</ixy>
            <ixz>0</ixz>
            <iyz>0</iyz>
          </inertia>
        </inertial>
        <collision name='collision'>
          <geometry>
            <mesh>
              <uri>model://drc_practice_ball_valve/meshes/ball_valve.dae</uri>
            </mesh>
          </geometry>
          <surface>
            <bounce>
              <restitution_coefficient>0.01</restitution_coefficient>
              <threshold>5</threshold>
            </bounce>
            <friction>
              <ode>
                <mu>5</mu>
                <mu2>5</mu2>
              </ode>
              <torsional>
                <ode/>
              </torsional>
            </friction>
            <contact>
              <ode>
                <soft_cfm>0.01</soft_cfm>
                <kp>10000</kp>
                <kd>1000</kd>
                <max_vel>0.01</max_vel>
                <min_depth>0.001</min_depth>
              </ode>
            </contact>
          </surface>
          <max_contacts>10</max_contacts>
        </collision>
        <visual name='visual'>
          <geometry>
            <mesh>
              <uri>model://drc_practice_ball_valve/meshes/ball_valve.dae</uri>
            </mesh>
          </geometry>
        </visual>
        <self_collide>0</self_collide>
        <enable_wind>0</enable_wind>
        <kinematic>0</kinematic>
      </link>
      <joint name='valve_9::ball' type='revolute'>
        <parent>world</parent>
        <child>valve_9::handle</child>
        <axis>
          <xyz expressed_in='valve_9::__model__'>0 1 0</xyz>
          <limit>
            <lower>0</lower>
            <upper>1.58</upper>
          </limit>
          <dynamics>
            <damping>0.3</damping>
            <friction>10</friction>
            <spring_reference>0</spring_reference>
            <spring_stiffness>0</spring_stiffness>
          </dynamics>
        </axis>
        <physics>
          <ode>
            <cfm_damping>1</cfm_damping>
            <limit>
              <cfm>0</cfm>
              <erp>0.2</erp>
            </limit>
          </ode>
        </physics>
      </joint>
      <frame name='valve_10::__model__' attached_to='valve_10::handle'>
        <pose relative_to='__model__'>0.309083 -0.0092 2.1162 0 -0 0</pose>
      </frame>
      <link name='valve_10::handle'>
        <pose relative_to='valve_10::__model__'>0 0.0275 0.02222 1.57079 9.3e-05 3.14159</pose>
        <inertial>
          <mass>0.0802</mass>
          <pose>0 0.0435 0.0055 0 -0 0</pose>
          <inertia>
            <ixx>3.8e-05</ixx>
            <iyy>4e-06</iyy>
            <izz>4e-05</izz>
            <ixy>0</ixy>
            <ixz>0</ixz>
            <iyz>0</iyz>
          </inertia>
        </inertial>
        <collision name='collision'>
          <geometry>
            <mesh>
              <uri>model://drc_practice_ball_valve/meshes/ball_valve.dae</uri>
            </mesh>
          </geometry>
          <surface>
            <bounce>
              <restitution_coefficient>0.01</restitution_coefficient>
              <threshold>5</threshold>
            </bounce>
            <friction>
              <ode>
                <mu>5</mu>
                <mu2>5</mu2>
              </ode>
              <torsional>
                <ode/>
              </torsional>
            </friction>
            <contact>
              <ode>
                <soft_cfm>0.01</soft_cfm>
                <kp>10000</kp>
                <kd>1000</kd>
                <max_vel>0.01</max_vel>
                <min_depth>0.001</min_depth>
              </ode>
            </contact>
          </surface>
          <max_contacts>10</max_contacts>
        </collision>
        <visual name='visual'>
          <geometry>
            <mesh>
              <uri>model://drc_practice_ball_valve/meshes/ball_valve.dae</uri>
            </mesh>
          </geometry>
        </visual>
        <self_collide>0</self_collide>
        <enable_wind>0</enable_wind>
        <kinematic>0</kinematic>
      </link>
      <joint name='valve_10::ball' type='revolute'>
        <parent>world</parent>
        <child>valve_10::handle</child>
        <axis>
          <xyz expressed_in='valve_10::__model__'>0 1 0</xyz>
          <limit>
            <lower>0</lower>
            <upper>1.58</upper>
          </limit>
          <dynamics>
            <damping>0.3</damping>
            <friction>10</friction>
            <spring_reference>0</spring_reference>
            <spring_stiffness>0</spring_stiffness>
          </dynamics>
        </axis>
        <physics>
          <ode>
            <cfm_damping>1</cfm_damping>
            <limit>
              <cfm>0</cfm>
              <erp>0.2</erp>
            </limit>
          </ode>
        </physics>
      </joint>
      <pose>5.45377 -3.01729 0 0 -0 0</pose>
    </model>
    <model name='Dumpster'>
      <link name='link'>
        <collision name='collision'>
          <geometry>
            <mesh>
              <scale>1.5 1.5 1.5</scale>
              <uri>model://dumpster/meshes/dumpster.dae</uri>
            </mesh>
          </geometry>
          <max_contacts>10</max_contacts>
          <surface>
            <contact>
              <ode/>
            </contact>
            <bounce/>
            <friction>
              <torsional>
                <ode/>
              </torsional>
              <ode/>
            </friction>
          </surface>
        </collision>
        <visual name='visual'>
          <geometry>
            <mesh>
              <scale>1.5 1.5 1.5</scale>
              <uri>model://dumpster/meshes/dumpster.dae</uri>
            </mesh>
          </geometry>
          <material>
            <script>
              <uri>model://dumpster/materials/scripts</uri>
              <uri>model://dumpster/materials/textures</uri>
              <name>Dumpster/Diffuse</name>
            </script>
          </material>
        </visual>
        <self_collide>0</self_collide>
        <inertial>
          <pose>0 0 0 0 -0 0</pose>
          <inertia>
            <ixx>1</ixx>
            <ixy>0</ixy>
            <ixz>0</ixz>
            <iyy>1</iyy>
            <iyz>0</iyz>
            <izz>1</izz>
          </inertia>
          <mass>1</mass>
        </inertial>
        <enable_wind>0</enable_wind>
        <kinematic>0</kinematic>
      </link>
      <pose>7.91018 0.77655 0 0 -0 0</pose>
    </model>
    <state world_name='default'>
      <sim_time>105 23000000</sim_time>
      <real_time>31 158771343</real_time>
      <wall_time>1722197692 18866366</wall_time>
      <iterations>24550</iterations>
      <model name='Dumpster'>
        <pose>7.91018 0.77655 0.001369 -2e-06 0 0</pose>
        <scale>1 1 1</scale>
        <link name='link'>
          <pose>7.91018 0.77655 0.001369 -2e-06 0 0</pose>
          <velocity>0 0 0 0 -0 0</velocity>
          <acceleration>0 0 -9.8 0 -0 0</acceleration>
          <wrench>0 0 -9.8 0 -0 0</wrench>
        </link>
      </model>
      <model name='ball_valve_wall'>
        <pose>5.45377 -3.01729 0 0 -0 0</pose>
        <scale>1 1 1</scale>
        <link name='valve_0::handle'>
          <pose>6.37336 -2.99899 0.30722 1.57079 9.3e-05 3.14159</pose>
          <velocity>-0 0 -0 0 -0 0</velocity>
          <acceleration>0 0 -0 0 -0 0</acceleration>
          <wrench>0 0 -0 0 -0 0</wrench>
        </link>
        <link name='valve_10::handle'>
          <pose>5.76285 -2.99899 2.13842 1.57079 9.3e-05 3.14159</pose>
          <velocity>0 0 0 0 -0 0</velocity>
          <acceleration>-0 -0 -0 0 -0 0</acceleration>
          <wrench>-0 -0 -0 0 -0 0</wrench>
        </link>
        <link name='valve_1::handle'>
          <pose>6.37336 -2.99899 0.91762 1.57079 9.3e-05 3.14159</pose>
          <velocity>-0 0 -0 0 -0 0</velocity>
          <acceleration>0 -0 -0 0 -0 0</acceleration>
          <wrench>0 -0 -0 0 -0 0</wrench>
        </link>
        <link name='valve_2::handle'>
          <pose>6.37336 -2.99899 1.52802 1.57079 9.3e-05 3.14159</pose>
          <velocity>-0 0 0 0 -0 0</velocity>
          <acceleration>-0 -0 -0 0 -0 0</acceleration>
          <wrench>-0 -0 -0 0 -0 0</wrench>
        </link>
        <link name='valve_3::handle'>
          <pose>6.37336 -2.99899 2.13842 1.57079 9.3e-05 3.14159</pose>
          <velocity>-0 0 0 0 -0 0</velocity>
          <acceleration>-0 0 -0 0 -0 0</acceleration>
          <wrench>-0 0 -0 0 -0 0</wrench>
        </link>
        <link name='valve_4::handle'>
          <pose>6.06811 -2.99899 0.61182 1.57079 9.3e-05 3.14159</pose>
          <velocity>-0 0 -0 0 -0 0</velocity>
          <acceleration>0 -0 -0 0 -0 0</acceleration>
          <wrench>0 -0 -0 0 -0 0</wrench>
        </link>
        <link name='valve_5::handle'>
          <pose>6.06811 -2.99899 1.22222 1.57079 9.3e-05 3.14159</pose>
          <velocity>-0 0 -0 0 -0 0</velocity>
          <acceleration>0 -0 -0 0 -0 0</acceleration>
          <wrench>0 -0 -0 0 -0 0</wrench>
        </link>
        <link name='valve_6::handle'>
          <pose>6.06811 -2.99899 1.83262 1.57079 9.3e-05 3.14159</pose>
          <velocity>-0 0 0 0 -0 0</velocity>
          <acceleration>0 -0 -0 0 -0 0</acceleration>
          <wrench>0 -0 -0 0 -0 0</wrench>
        </link>
        <link name='valve_7::handle'>
          <pose>5.76285 -2.99899 0.30722 1.57079 9.3e-05 3.14159</pose>
          <velocity>0 0 -0 0 -0 0</velocity>
          <acceleration>-0 0 -0 0 -0 0</acceleration>
          <wrench>-0 0 -0 0 -0 0</wrench>
        </link>
        <link name='valve_8::handle'>
          <pose>5.76285 -2.99899 0.91762 1.57079 9.3e-05 3.14159</pose>
          <velocity>0 0 -0 0 -0 0</velocity>
          <acceleration>0 -0 -0 0 -0 0</acceleration>
          <wrench>0 -0 -0 0 -0 0</wrench>
        </link>
        <link name='valve_9::handle'>
          <pose>5.76285 -2.99899 1.52802 1.57079 9.3e-05 3.14159</pose>
          <velocity>0 0 0 0 -0 0</velocity>
          <acceleration>-0 -0 -0 0 -0 0</acceleration>
          <wrench>-0 -0 -0 0 -0 0</wrench>
        </link>
        <link name='wall::link'>
          <pose>5.45377 -3.01729 0 0 -0 0</pose>
          <velocity>0 0 -0 0 -0 0</velocity>
          <acceleration>0 0 -0 0 -0 0</acceleration>
          <wrench>0 0 -0 0 -0 0</wrench>
        </link>
      </model>
      <model name='cafe_table'>
        <pose>5.37115 -2.01626 0 0 -0 0</pose>
        <scale>1 1 1</scale>
        <link name='link'>
          <pose>5.37115 -2.01626 0 0 -0 0</pose>
          <velocity>0 0 0 0 -0 0</velocity>
          <acceleration>0 0 0 0 -0 0</acceleration>
          <wrench>0 0 0 0 -0 0</wrench>
        </link>
      </model>
      <model name='ground_plane'>
        <pose>0 0 0 0 -0 0</pose>
        <scale>1 1 1</scale>
        <link name='link'>
          <pose>0 0 0 0 -0 0</pose>
          <velocity>0 0 0 0 -0 0</velocity>
          <acceleration>0 0 0 0 -0 0</acceleration>
          <wrench>0 0 0 0 -0 0</wrench>
        </link>
      </model>
      <model name='model'>
        <pose>6.78089 -4.87878 0 0 -0 0</pose>
        <scale>1 1 1</scale>
        <link name='Door_1'>
          <pose>5.70527 -4.81788 0 0 -0 0</pose>
          <velocity>0 0 0 0 -0 0</velocity>
          <acceleration>0 0 0 0 -0 0</acceleration>
          <wrench>0 0 0 0 -0 0</wrench>
        </link>
        <link name='Wall_0'>
          <pose>6.6538 -1.37919 0 0 -0 0</pose>
          <velocity>0 0 0 0 -0 0</velocity>
          <acceleration>0 0 0 0 -0 0</acceleration>
          <wrench>0 0 0 0 -0 0</wrench>
        </link>
        <link name='Wall_1'>
          <pose>9.0788 -3.05419 0 0 0 -1.5708</pose>
          <velocity>0 0 0 0 -0 0</velocity>
          <acceleration>0 0 0 0 -0 0</acceleration>
          <wrench>0 0 0 0 -0 0</wrench>
        </link>
        <link name='Wall_12'>
          <pose>6.7788 -9.07919 0 0 -0 0</pose>
          <velocity>0 0 0 0 -0 0</velocity>
          <acceleration>0 0 0 0 -0 0</acceleration>
          <wrench>0 0 0 0 -0 0</wrench>
        </link>
        <link name='Wall_13'>
          <pose>9.2038 -6.90419 0 0 -0 1.6282</pose>
          <velocity>0 0 0 0 -0 0</velocity>
          <acceleration>0 0 0 0 -0 0</acceleration>
          <wrench>0 0 0 0 -0 0</wrench>
        </link>
        <link name='Wall_2'>
          <pose>6.6538 -4.72919 0 0 -0 3.14159</pose>
          <velocity>0 0 0 0 -0 0</velocity>
          <acceleration>0 0 0 0 -0 0</acceleration>
          <wrench>0 0 0 0 -0 0</wrench>
        </link>
        <link name='Wall_3'>
          <pose>4.2288 -3.05419 0 0 -0 1.5708</pose>
          <velocity>0 0 0 0 -0 0</velocity>
          <acceleration>0 0 0 0 -0 0</acceleration>
          <wrench>0 0 0 0 -0 0</wrench>
        </link>
        <link name='Wall_5'>
          <pose>4.92937 -2.78295 0 0 -0 3.14159</pose>
          <velocity>0 0 0 0 -0 0</velocity>
          <acceleration>0 0 0 0 -0 0</acceleration>
          <wrench>0 0 0 0 -0 0</wrench>
        </link>
        <link name='Wall_6'>
          <pose>6.67938 -2.78295 0 0 -0 0</pose>
          <velocity>0 0 0 0 -0 0</velocity>
          <acceleration>0 0 0 0 -0 0</acceleration>
          <wrench>0 0 0 0 -0 0</wrench>
        </link>
        <link name='Wall_8'>
          <pose>4.2288 -6.90419 0 0 0 -1.5708</pose>
          <velocity>0 0 0 0 -0 0</velocity>
          <acceleration>0 0 0 0 -0 0</acceleration>
          <wrench>0 0 0 0 -0 0</wrench>
        </link>
      </model>
      <model name='model_0'>
        <pose>5.60332 -7.69641 0.272645 -2.9e-05 -1.26073 0.004531</pose>
        <scale>1 1 1</scale>
        <link name='link_0'>
          <pose>4.94674 -7.69536 0.491413 -2.9e-05 -1.26073 0.004531</pose>
          <velocity>0.000699 -0.00044 -0.003531 0.000604 -0.004638 -0.000336</velocity>
          <acceleration>-1.82358 -0.77664 -7.0618 -1.93457 -0.148491 2.33876</acceleration>
          <wrench>-1.82358 -0.77664 -7.0618 0 -0 0</wrench>
        </link>
        <link name='link_1'>
          <pose>5.4645 -7.71303 0.304548 -3.2e-05 -1.26073 0.004534</pose>
          <velocity>0.001451 -0.000252 -0.001283 0.000867 -0.004449 -0.000205</velocity>
          <acceleration>-0.321861 -0.469871 -2.56524 -1.12868 -0.527201 2.58924</acceleration>
          <wrench>-0.321861 -0.469871 -2.56524 0 -0 0</wrench>
        </link>
        <link name='link_2'>
          <pose>5.89295 -7.6911 0.167241 -3.3e-05 -1.26073 0.004534</pose>
          <velocity>0.002053 -0.000223 0.000626 0.00091 -0.004432 -0.000232</velocity>
          <acceleration>0.885157 -0.467377 1.25126 -1.32094 -0.560637 2.54607</acceleration>
          <wrench>0.885157 -0.467377 1.25126 0 -0 0</wrench>
        </link>
        <link name='link_3'>
          <pose>5.85871 -8.24142 0.200013 1.57044 0.775105 0.003496</pose>
          <velocity>0.001669 -0.000187 -4.6e-05 0.000943 0.008421 -0.000312</velocity>
          <acceleration>0.045168 -0.390813 -0.091519 2.04469 0.347378 -0.652532</acceleration>
          <wrench>0.045168 -0.390813 -0.091519 0 -0 0</wrench>
        </link>
        <link name='link_3_clone'>
          <pose>5.85372 -7.14112 0.200013 1.57043 0.803075 0.003483</pose>
          <velocity>0.002042 -0.000187 0.00095 0.000926 0.010271 -0.000256</velocity>
          <acceleration>0.934543 -0.389253 1.89907 1.92851 0.007056 -0.54588</acceleration>
          <wrench>0.934543 -0.389253 1.89907 0 -0 0</wrench>
        </link>
      </model>
      <model name='model_0_clone'>
        <pose>5.58594 -3.74708 0.272645 -2.9e-05 -1.26073 0.004531</pose>
        <scale>1 1 1</scale>
        <link name='link_0'>
          <pose>4.92936 -3.74603 0.491413 -2.9e-05 -1.26073 0.004531</pose>
          <velocity>0.000699 -0.00044 -0.003531 0.000604 -0.004638 -0.000336</velocity>
          <acceleration>-1.82358 -0.77664 -7.0618 -1.93457 -0.148491 2.33876</acceleration>
          <wrench>-1.82358 -0.77664 -7.0618 0 -0 0</wrench>
        </link>
        <link name='link_1'>
          <pose>5.44712 -3.7637 0.304548 -3.2e-05 -1.26073 0.004534</pose>
          <velocity>0.001451 -0.000252 -0.001283 0.000867 -0.004449 -0.000205</velocity>
          <acceleration>-0.321861 -0.469871 -2.56524 -1.12868 -0.527201 2.58924</acceleration>
          <wrench>-0.321861 -0.469871 -2.56524 0 -0 0</wrench>
        </link>
        <link name='link_2'>
          <pose>5.87556 -3.74177 0.167241 -3.3e-05 -1.26073 0.004534</pose>
          <velocity>0.002053 -0.000223 0.000626 0.00091 -0.004432 -0.000232</velocity>
          <acceleration>0.885157 -0.467377 1.25126 -1.32094 -0.560637 2.54607</acceleration>
          <wrench>0.885157 -0.467377 1.25126 0 -0 0</wrench>
        </link>
        <link name='link_3'>
          <pose>5.84133 -4.29209 0.200013 1.57044 0.775105 0.003496</pose>
          <velocity>0.001669 -0.000187 -4.6e-05 0.000943 0.008421 -0.000312</velocity>
          <acceleration>0.045168 -0.390813 -0.091519 2.04469 0.347378 -0.652532</acceleration>
          <wrench>0.045168 -0.390813 -0.091519 0 -0 0</wrench>
        </link>
        <link name='link_3_clone'>
          <pose>5.83634 -3.19179 0.200013 1.57043 0.803075 0.003483</pose>
          <velocity>0.002042 -0.000187 0.00095 0.000926 0.010271 -0.000256</velocity>
          <acceleration>0.934543 -0.389253 1.89907 1.92851 0.007056 -0.54588</acceleration>
          <wrench>0.934543 -0.389253 1.89907 0 -0 0</wrench>
        </link>
      </model>
      <model name='my_robot'>
        <pose>5.45011 -5.65001 0.1 0 0.000667 3.8e-05</pose>
        <scale>1 1 1</scale>
        <link name='left_wheel'>
          <pose>5.4501 -5.50001 0.1 0 0.000995 3.8e-05</pose>
          <velocity>1.5e-05 1e-06 -0 -5e-06 0.000152 1e-06</velocity>
          <acceleration>0.035703 0.001248 -0.000631 -0.012424 0.356674 -0.000185</acceleration>
          <wrench>0.178515 0.006241 -0.003156 0 -0 0</wrench>
        </link>
        <link name='right_wheel'>
          <pose>5.45012 -5.80001 0.1 0 0.001257 3.8e-05</pose>
          <velocity>1.5e-05 -0 -0 -0 0.000152 -2e-06</velocity>
          <acceleration>0.035094 -0.000186 -0.000598 0.00223 0.349255 -0.005302</acceleration>
          <wrench>0.175468 -0.000932 -0.002989 0 -0 0</wrench>
        </link>
        <link name='robot_footprint'>
          <pose>5.45011 -5.65001 0.1 0 0.000667 3.8e-05</pose>
          <velocity>1.5e-05 1e-06 1e-06 -5e-06 0.000152 0</velocity>
          <acceleration>0.035374 0.001651 0.001812 -0.009698 0.353001 -0.001965</acceleration>
          <wrench>0.534153 0.024932 0.027368 0 -0 0</wrench>
        </link>
      </model>
      <model name='whiteball'>
        <pose>6.28161 -5.65265 0.07793 0 -0 0</pose>
        <scale>1 1 1</scale>
        <link name='link_0'>
          <pose>6.28161 -5.65265 0.07793 0 -0 0</pose>
          <velocity>0 0 0 0 -0 0</velocity>
          <acceleration>0 0 0 0 -0 0</acceleration>
          <wrench>0 0 0 0 -0 0</wrench>
        </link>
      </model>
      <light name='sun'>
        <pose>0 0 10 0 -0 0</pose>
      </light>
    </state>
    <gui fullscreen='0'>
      <camera name='user_camera'>
        <pose>8.61663 -6.39883 2.50061 -0 0.821655 2.72893</pose>
        <view_controller>orbit</view_controller>
        <projection_type>perspective</projection_type>
      </camera>
    </gui>
    <model name='my_robot'>
      <link name='robot_footprint'>
        <inertial>
          <pose>0.001325 0 0 0 -0 0</pose>
          <mass>15.1</mass>
          <inertia>
            <ixx>0.100002</ixx>
            <ixy>0</ixy>
            <ixz>-1.48675e-07</ixz>
            <iyy>0.103976</iyy>
            <iyz>0</iyz>
            <izz>0.103976</izz>
          </inertia>
        </inertial>
        <collision name='robot_footprint_fixed_joint_lump__collision_collision'>
          <pose>0 0 0 0 -0 0</pose>
          <geometry>
            <box>
              <size>0.4 0.2 0.1</size>
            </box>
          </geometry>
          <max_contacts>10</max_contacts>
          <surface>
            <contact>
              <ode/>
            </contact>
            <bounce/>
            <friction>
              <torsional>
                <ode/>
              </torsional>
              <ode/>
            </friction>
          </surface>
        </collision>
        <collision name='robot_footprint_fixed_joint_lump__back_caster_collision_collision_1'>
          <pose>-0.15 0 -0.05 0 -0 0</pose>
          <geometry>
            <sphere>
              <radius>0.0499</radius>
            </sphere>
          </geometry>
          <max_contacts>10</max_contacts>
          <surface>
            <contact>
              <ode/>
            </contact>
            <bounce/>
            <friction>
              <torsional>
                <ode/>
              </torsional>
              <ode/>
            </friction>
          </surface>
        </collision>
        <collision name='robot_footprint_fixed_joint_lump__front_caster_collision_collision_2'>
          <pose>0.15 0 -0.05 0 -0 0</pose>
          <geometry>
            <sphere>
              <radius>0.0499</radius>
            </sphere>
          </geometry>
          <max_contacts>10</max_contacts>
          <surface>
            <contact>
              <ode/>
            </contact>
            <bounce/>
            <friction>
              <torsional>
                <ode/>
              </torsional>
              <ode/>
            </friction>
          </surface>
        </collision>
        <collision name='robot_footprint_fixed_joint_lump__camera_collision_3'>
          <pose>0.2 0 0 0 -0 0</pose>
          <geometry>
            <box>
              <size>0.05 0.05 0.05</size>
            </box>
          </geometry>
          <surface>
            <contact>
              <ode/>
            </contact>
            <friction>
              <ode/>
              <torsional>
                <ode/>
              </torsional>
            </friction>
            <bounce/>
          </surface>
          <max_contacts>10</max_contacts>
        </collision>
        <collision name='robot_footprint_fixed_joint_lump__hokuyo_collision_4'>
          <pose>0.15 0 0.1 0 -0 0</pose>
          <geometry>
            <box>
              <size>0.1 0.1 0.1</size>
            </box>
          </geometry>
          <surface>
            <contact>
              <ode/>
            </contact>
            <friction>
              <ode/>
              <torsional>
                <ode/>
              </torsional>
            </friction>
            <bounce/>
          </surface>
          <max_contacts>10</max_contacts>
        </collision>
        <visual name='robot_footprint_fixed_joint_lump__chassis_visual_visual'>
          <pose>0 0 0 0 -0 0</pose>
          <geometry>
            <box>
              <size>0.4 0.2 0.1</size>
            </box>
          </geometry>
        </visual>
        <visual name='robot_footprint_fixed_joint_lump__back_caster_visual_visual_1'>
          <pose>-0.15 0 -0.05 0 -0 0</pose>
          <geometry>
            <sphere>
              <radius>0.05</radius>
            </sphere>
          </geometry>
        </visual>
        <visual name='robot_footprint_fixed_joint_lump__front_caster_visual_visual_2'>
          <pose>0.15 0 -0.05 0 -0 0</pose>
          <geometry>
            <sphere>
              <radius>0.05</radius>
            </sphere>
          </geometry>
        </visual>
        <visual name='robot_footprint_fixed_joint_lump__camera_visual_3'>
          <pose>0.2 0 0 0 -0 0</pose>
          <geometry>
            <box>
              <size>0.05 0.05 0.05</size>
            </box>
          </geometry>
        </visual>
        <visual name='robot_footprint_fixed_joint_lump__hokuyo_visual_4'>
          <pose>0.15 0 0.1 0 -0 0</pose>
          <geometry>
            <mesh>
              <scale>1 1 1</scale>
              <uri>/home/ubuntu/ChaseIt/src/my_robot/meshes/hokuyo.dae</uri>
            </mesh>
          </geometry>
        </visual>
        <sensor name='camera1' type='camera'>
          <update_rate>30</update_rate>
          <camera name='head'>
            <horizontal_fov>1.39626</horizontal_fov>
            <image>
              <width>800</width>
              <height>800</height>
              <format>R8G8B8</format>
            </image>
            <clip>
              <near>0.02</near>
              <far>300</far>
            </clip>
          </camera>
          <plugin name='camera_controller' filename='libgazebo_ros_camera.so'>
            <alwaysOn>1</alwaysOn>
            <updateRate>0.0</updateRate>
            <cameraName>camera</cameraName>
            <imageTopicName>rgb/image_raw</imageTopicName>
            <cameraInfoTopicName>rgb/camera_info</cameraInfoTopicName>
            <frameName>camera</frameName>
            <hackBaseline>0.07</hackBaseline>
            <distortionK1>0.0</distortionK1>
            <distortionK2>0.0</distortionK2>
            <distortionK3>0.0</distortionK3>
            <distortionT1>0.0</distortionT1>
            <distortionT2>0.0</distortionT2>
            <robotNamespace>/</robotNamespace>
          </plugin>
          <pose>0.2 0 0 0 -0 0</pose>
        </sensor>
        <sensor name='head_hokuyo_sensor' type='ray'>
          <visualize>0</visualize>
          <update_rate>40</update_rate>
          <ray>
            <scan>
              <horizontal>
                <samples>720</samples>
                <resolution>1</resolution>
                <min_angle>-1.5708</min_angle>
                <max_angle>1.5708</max_angle>
              </horizontal>
              <vertical>
                <samples>1</samples>
                <min_angle>0</min_angle>
                <max_angle>0</max_angle>
              </vertical>
            </scan>
            <range>
              <min>0.1</min>
              <max>30</max>
              <resolution>0.01</resolution>
            </range>
            <noise>
              <type>gaussian</type>
              <mean>0</mean>
              <stddev>0.01</stddev>
            </noise>
          </ray>
          <plugin name='gazebo_ros_head_hokuyo_controller' filename='libgazebo_ros_laser.so'>
            <topicName>/scan</topicName>
            <frameName>hokuyo</frameName>
            <robotNamespace>/</robotNamespace>
          </plugin>
          <pose>0.15 0 0.1 0 -0 0</pose>
        </sensor>
        <self_collide>0</self_collide>
        <enable_wind>0</enable_wind>
        <kinematic>0</kinematic>
      </link>
      <joint name='left_wheel_hinge' type='revolute'>
        <pose relative_to='robot_footprint'>0 0.15 0 0 -0 0</pose>
        <parent>robot_footprint</parent>
        <child>left_wheel</child>
        <axis>
          <xyz>0 1 0</xyz>
          <limit>
            <effort>10000</effort>
            <velocity>1000</velocity>
            <lower>-1e+16</lower>
            <upper>1e+16</upper>
          </limit>
          <dynamics>
            <damping>1</damping>
            <friction>1</friction>
            <spring_reference>0</spring_reference>
            <spring_stiffness>0</spring_stiffness>
          </dynamics>
        </axis>
      </joint>
      <link name='left_wheel'>
        <pose relative_to='left_wheel_hinge'>0 0 0 0 -0 0</pose>
        <inertial>
          <pose>0 0 0 -0 1.5707 1.5707</pose>
          <mass>5</mass>
          <inertia>
            <ixx>0.1</ixx>
            <ixy>0</ixy>
            <ixz>0</ixz>
            <iyy>0.1</iyy>
            <iyz>0</iyz>
            <izz>0.1</izz>
          </inertia>
        </inertial>
        <collision name='left_wheel_fixed_joint_lump__collision_collision'>
          <pose>0 0 0 1.57089 1.57079 -3.14159</pose>
          <geometry>
            <cylinder>
              <length>0.05</length>
              <radius>0.1</radius>
            </cylinder>
          </geometry>
          <max_contacts>10</max_contacts>
          <surface>
            <contact>
              <ode/>
            </contact>
            <bounce/>
            <friction>
              <torsional>
                <ode/>
              </torsional>
              <ode/>
            </friction>
          </surface>
        </collision>
        <visual name='left_wheel_visual_visual'>
          <pose>0 0 0 1.57089 1.57079 -3.14159</pose>
          <geometry>
            <cylinder>
              <length>0.05</length>
              <radius>0.1</radius>
            </cylinder>
          </geometry>
        </visual>
        <self_collide>0</self_collide>
        <enable_wind>0</enable_wind>
        <kinematic>0</kinematic>
      </link>
      <joint name='right_wheel_hinge' type='revolute'>
        <pose relative_to='robot_footprint'>0 -0.15 0 0 -0 0</pose>
        <parent>robot_footprint</parent>
        <child>right_wheel</child>
        <axis>
          <xyz>0 1 0</xyz>
          <limit>
            <effort>10000</effort>
            <velocity>1000</velocity>
            <lower>-1e+16</lower>
            <upper>1e+16</upper>
          </limit>
          <dynamics>
            <damping>1</damping>
            <friction>1</friction>
            <spring_reference>0</spring_reference>
            <spring_stiffness>0</spring_stiffness>
          </dynamics>
        </axis>
      </joint>
      <link name='right_wheel'>
        <pose relative_to='right_wheel_hinge'>0 0 0 0 -0 0</pose>
        <inertial>
          <pose>0 0 0 -0 1.5707 1.5707</pose>
          <mass>5</mass>
          <inertia>
            <ixx>0.1</ixx>
            <ixy>0</ixy>
            <ixz>0</ixz>
            <iyy>0.1</iyy>
            <iyz>0</iyz>
            <izz>0.1</izz>
          </inertia>
        </inertial>
        <collision name='right_wheel_fixed_joint_lump__collision_collision'>
          <pose>0 0 0 1.57089 1.57079 -3.14159</pose>
          <geometry>
            <cylinder>
              <length>0.05</length>
              <radius>0.1</radius>
            </cylinder>
          </geometry>
          <max_contacts>10</max_contacts>
          <surface>
            <contact>
              <ode/>
            </contact>
            <bounce/>
            <friction>
              <torsional>
                <ode/>
              </torsional>
              <ode/>
            </friction>
          </surface>
        </collision>
        <visual name='right_wheel_visual_visual'>
          <pose>0 0 0 1.57089 1.57079 -3.14159</pose>
          <geometry>
            <cylinder>
              <length>0.05</length>
              <radius>0.1</radius>
            </cylinder>
          </geometry>
        </visual>
        <self_collide>0</self_collide>
        <enable_wind>0</enable_wind>
        <kinematic>0</kinematic>
      </link>
      <static>0</static>
      <plugin name='differential_drive_controller' filename='libgazebo_ros_diff_drive.so'>
        <legacyMode>0</legacyMode>
        <alwaysOn>1</alwaysOn>
        <updateRate>10</updateRate>
        <leftJoint>left_wheel_hinge</leftJoint>
        <rightJoint>right_wheel_hinge</rightJoint>
        <wheelSeparation>0.4</wheelSeparation>
        <wheelDiameter>0.2</wheelDiameter>
        <torque>10</torque>
        <commandTopic>cmd_vel</commandTopic>
        <odometryTopic>odom</odometryTopic>
        <odometryFrame>odom</odometryFrame>
        <robotBaseFrame>robot_footprint</robotBaseFrame>
        <publishWheelTF>0</publishWheelTF>
        <publishWheelJointState>0</publishWheelJointState>
        <rosDebugLevel>na</rosDebugLevel>
        <wheelAcceleration>0</wheelAcceleration>
        <wheelTorque>5</wheelTorque>
        <odometrySource>world</odometrySource>
        <publishTf>1</publishTf>
        <publishOdomTF>1</publishOdomTF>
        <robotNamespace>/</robotNamespace>
      </plugin>
      <pose>5.45 -5.65 0 0 -0 0</pose>
    </model>
    <model name='whiteball'>
      <link name='link_0'>
        <inertial>
          <mass>1</mass>
          <inertia>
            <ixx>0.1</ixx>
            <ixy>0</ixy>
            <ixz>0</ixz>
            <iyy>0.1</iyy>
            <iyz>0</iyz>
            <izz>0.1</izz>
          </inertia>
          <pose>0 0 0 0 -0 0</pose>
        </inertial>
        <pose>0 0 0 0 -0 0</pose>
        <gravity>1</gravity>
        <self_collide>0</self_collide>
        <kinematic>0</kinematic>
        <enable_wind>0</enable_wind>
        <visual name='visual'>
          <pose>0 0 0 0 -0 0</pose>
          <geometry>
            <sphere>
              <radius>0.1</radius>
            </sphere>
          </geometry>
          <material>
            <lighting>1</lighting>
            <script>
              <uri>file://media/materials/scripts/gazebo.material</uri>
              <name>Gazebo/Grey</name>
            </script>
            <shader type='pixel'>
              <normal_map>__default__</normal_map>
            </shader>
            <ambient>1 1 1 1</ambient>
            <diffuse>1 1 1 1</diffuse>
            <specular>1 1 1 1</specular>
            <emissive>1 1 1 1</emissive>
          </material>
          <transparency>0</transparency>
          <cast_shadows>1</cast_shadows>
        </visual>
        <collision name='collision'>
          <laser_retro>0</laser_retro>
          <max_contacts>10</max_contacts>
          <pose>0 0 0 0 -0 0</pose>
          <geometry>
            <sphere>
              <radius>0.1</radius>
            </sphere>
          </geometry>
          <surface>
            <friction>
              <ode>
                <mu>1</mu>
                <mu2>1</mu2>
                <fdir1>0 0 0</fdir1>
                <slip1>0</slip1>
                <slip2>0</slip2>
              </ode>
              <torsional>
                <coefficient>1</coefficient>
                <patch_radius>0</patch_radius>
                <surface_radius>0</surface_radius>
                <use_patch_radius>1</use_patch_radius>
                <ode>
                  <slip>0</slip>
                </ode>
              </torsional>
            </friction>
            <bounce>
              <restitution_coefficient>0</restitution_coefficient>
              <threshold>1e+06</threshold>
            </bounce>
            <contact>
              <collide_without_contact>0</collide_without_contact>
              <collide_without_contact_bitmask>1</collide_without_contact_bitmask>
              <collide_bitmask>1</collide_bitmask>
              <ode>
                <soft_cfm>0</soft_cfm>
                <soft_erp>0.2</soft_erp>
                <kp>1e+13</kp>
                <kd>1</kd>
                <max_vel>0.01</max_vel>
                <min_depth>0</min_depth>
              </ode>
              <bullet>
                <split_impulse>1</split_impulse>
                <split_impulse_penetration_threshold>-0.01</split_impulse_penetration_threshold>
                <soft_cfm>0</soft_cfm>
                <soft_erp>0.2</soft_erp>
                <kp>1e+13</kp>
                <kd>1</kd>
              </bullet>
            </contact>
          </surface>
        </collision>
      </link>
      <static>0</static>
      <allow_auto_disable>1</allow_auto_disable>
      <pose>6.91226 -5.65265 0.5 0 -0 0</pose>
    </model>
  </world>
</sdf>
